5:return {{["y"] = 0, ["x"] = 0, ["name"] = "default:dirt_with_dry_grass", ["z"] = 0, ["meta"] = {["inventory"] = {}, ["fields"] = {}}}, {["y"] = 0, ["x"] = 0, ["name"] = "default:dirt", ["z"] = 1, ["meta"] = {["inventory"] = {}, ["fields"] = {}}}, {["y"] = 0, ["x"] = 0, ["name"] = "default:dirt", ["z"] = 2, ["meta"] = {["inventory"] = {}, ["fields"] = {}}}, {["y"] = 0, ["x"] = 0, ["name"] = "default:dirt", ["z"] = 3, ["meta"] = {["inventory"] = {}, ["fields"] = {}}}, {["y"] = 0, ["x"] = 0, ["name"] = "default:dirt", ["z"] = 4, ["meta"] = {["inventory"] = {}, ["fields"] = {}}}, {["y"] = 0, ["x"] = 0, ["name"] = "default:stone", ["z"] = 5, ["meta"] = {["inventory"] = {}, ["fields"] = {}}}, {["y"] = 0, ["x"] = 0, ["name"] = "default:stone", ["z"] = 6, ["meta"] = {["inventory"] = {}, ["fields"] = {}}}, {["y"] = 0, ["x"] = 0, ["name"] = "default:stone", ["z"] = 7, ["meta"] = {["inventory"] = {}, ["fields"] = {}}}, {["y"] = 0, ["x"] = 0, ["name"] = "default:stone", ["z"] = 8, ["meta"] = {["inventory"] = {}, ["fields"] = {}}}, {["y"] = 0, ["x"] = 0, ["name"] = "default:dirt", ["z"] = 9, ["meta"] = {["inventory"] = {}, ["fields"] = {}}}, {["y"] = 0, ["x"] = 0, ["name"] = "default:dirt", ["z"] = 10, ["meta"] = {["inventory"] = {}, ["fields"] = {}}}, {["y"] = 0, ["x"] = 0, ["name"] = "default:dirt", ["z"] = 11, ["meta"] = {["inventory"] = {}, ["fields"] = {}}}, {["y"] = 1, ["x"] = 0, ["name"] = "default:acacia_wood", ["z"] = 1, ["meta"] = {["inventory"] = {}, ["fields"] = {}}}, {["y"] = 1, ["x"] = 0, ["name"] = "default:acacia_wood", ["z"] = 2, ["meta"] = {["inventory"] = {}, ["fields"] = {}}}, {["y"] = 1, ["x"] = 0, ["name"] = "default:acacia_wood", ["z"] = 3, ["meta"] = {["inventory"] = {}, ["fields"] = {}}}, {["y"] = 1, ["x"] = 0, ["name"] = "default:acacia_wood", ["z"] = 4, ["meta"] = {["inventory"] = {}, ["fields"] = {}}}, {["y"] = 1, ["x"] = 0, ["name"] = "default:acacia_wood", ["z"] = 5, ["meta"] = {["inventory"] = {}, ["fields"] = {}}}, {["y"] = 1, ["x"] = 0, ["name"] = "default:acacia_wood", ["z"] = 6, ["meta"] = {["inventory"] = {}, ["fields"] = {}}}, {["y"] = 1, ["x"] = 0, ["name"] = "default:acacia_wood", ["z"] = 7, ["meta"] = {["inventory"] = {}, ["fields"] = {}}}, {["y"] = 1, ["x"] = 0, ["name"] = "default:acacia_wood", ["z"] = 8, ["meta"] = {["inventory"] = {}, ["fields"] = {}}}, {["y"] = 1, ["x"] = 0, ["name"] = "default:acacia_wood", ["z"] = 9, ["meta"] = {["inventory"] = {}, ["fields"] = {}}}, {["y"] = 1, ["x"] = 0, ["name"] = "default:acacia_wood", ["z"] = 10, ["meta"] = {["inventory"] = {}, ["fields"] = {}}}, {["y"] = 1, ["x"] = 0, ["name"] = "default:acacia_wood", ["z"] = 11, ["meta"] = {["inventory"] = {}, ["fields"] = {}}}, {["y"] = 2, ["x"] = 0, ["name"] = "default:acacia_wood", ["z"] = 1, ["meta"] = {["inventory"] = {}, ["fields"] = {}}}, {["y"] = 2, ["x"] = 0, ["name"] = "default:acacia_wood", ["z"] = 2, ["meta"] = {["inventory"] = {}, ["fields"] = {}}}, {["y"] = 2, ["x"] = 0, ["name"] = "default:acacia_wood", ["z"] = 3, ["meta"] = {["inventory"] = {}, ["fields"] = {}}}, {["y"] = 2, ["x"] = 0, ["name"] = "default:acacia_wood", ["z"] = 4, ["meta"] = {["inventory"] = {}, ["fields"] = {}}}, {["y"] = 2, ["x"] = 0, ["name"] = "default:acacia_wood", ["z"] = 5, ["meta"] = {["inventory"] = {}, ["fields"] = {}}}, {["y"] = 2, ["x"] = 0, ["name"] = "default:acacia_wood", ["z"] = 6, ["meta"] = {["inventory"] = {}, ["fields"] = {}}}, {["y"] = 2, ["x"] = 0, ["name"] = "default:acacia_wood", ["z"] = 7, ["meta"] = {["inventory"] = {}, ["fields"] = {}}}, {["y"] = 2, ["x"] = 0, ["name"] = "default:acacia_wood", ["z"] = 8, ["meta"] = {["inventory"] = {}, ["fields"] = {}}}, {["y"] = 2, ["x"] = 0, ["name"] = "default:acacia_wood", ["z"] = 9, ["meta"] = {["inventory"] = {}, ["fields"] = {}}}, {["y"] = 2, ["x"] = 0, ["name"] = "default:acacia_wood", ["z"] = 10, ["meta"] = {["inventory"] = {}, ["fields"] = {}}}, {["y"] = 2, ["x"] = 0, ["name"] = "default:acacia_wood", ["z"] = 11, ["meta"] = {["inventory"] = {}, ["fields"] = {}}}, {["y"] = 3, ["x"] = 0, ["name"] = "default:wood", ["z"] = 1, ["meta"] = {["inventory"] = {}, ["fields"] = {}}}, {["y"] = 3, ["x"] = 0, ["name"] = "default:wood", ["z"] = 2, ["meta"] = {["inventory"] = {}, ["fields"] = {}}}, {["y"] = 3, ["x"] = 0, ["name"] = "default:wood", ["z"] = 3, ["meta"] = {["inventory"] = {}, ["fields"] = {}}}, {["y"] = 3, ["x"] = 0, ["name"] = "default:wood", ["z"] = 4, ["meta"] = {["inventory"] = {}, ["fields"] = {}}}, {["y"] = 3, ["x"] = 0, ["name"] = "default:wood", ["z"] = 5, ["meta"] = {["inventory"] = {}, ["fields"] = {}}}, {["y"] = 3, ["x"] = 0, ["name"] = "default:wood", ["z"] = 6, ["meta"] = {["inventory"] = {}, ["fields"] = {}}}, {["y"] = 3, ["x"] = 0, ["name"] = "default:wood", ["z"] = 7, ["meta"] = {["inventory"] = {}, ["fields"] = {}}}, {["y"] = 3, ["x"] = 0, ["name"] = "default:wood", ["z"] = 8, ["meta"] = {["inventory"] = {}, ["fields"] = {}}}, {["y"] = 3, ["x"] = 0, ["name"] = "default:wood", ["z"] = 9, ["meta"] = {["inventory"] = {}, ["fields"] = {}}}, {["y"] = 3, ["x"] = 0, ["name"] = "default:wood", ["z"] = 10, ["meta"] = {["inventory"] = {}, ["fields"] = {}}}, {["y"] = 3, ["x"] = 0, ["name"] = "default:wood", ["z"] = 11, ["meta"] = {["inventory"] = {}, ["fields"] = {}}}, {["y"] = 4, ["x"] = 0, ["name"] = "default:sandstone", ["z"] = 1, ["meta"] = {["inventory"] = {}, ["fields"] = {}}}, {["y"] = 4, ["x"] = 0, ["name"] = "default:sandstone", ["z"] = 2, ["meta"] = {["inventory"] = {}, ["fields"] = {}}}, {["y"] = 4, ["x"] = 0, ["name"] = "default:sandstone", ["z"] = 3, ["meta"] = {["inventory"] = {}, ["fields"] = {}}}, {["y"] = 4, ["x"] = 0, ["name"] = "default:sandstone", ["z"] = 4, ["meta"] = {["inventory"] = {}, ["fields"] = {}}}, {["y"] = 4, ["x"] = 0, ["name"] = "default:sandstone", ["z"] = 5, ["meta"] = {["inventory"] = {}, ["fields"] = {}}}, {["y"] = 4, ["x"] = 0, ["name"] = "default:sandstone", ["z"] = 6, ["meta"] = {["inventory"] = {}, ["fields"] = {}}}, {["y"] = 4, ["x"] = 0, ["name"] = "default:sandstone", ["z"] = 7, ["meta"] = {["inventory"] = {}, ["fields"] = {}}}, {["y"] = 4, ["x"] = 0, ["name"] = "default:sandstone", ["z"] = 8, ["meta"] = {["inventory"] = {}, ["fields"] = {}}}, {["y"] = 4, ["x"] = 0, ["name"] = "default:sandstone", ["z"] = 9, ["meta"] = {["inventory"] = {}, ["fields"] = {}}}, {["y"] = 4, ["x"] = 0, ["name"] = "default:sandstone", ["z"] = 10, ["meta"] = {["inventory"] = {}, ["fields"] = {}}}, {["y"] = 4, ["x"] = 0, ["name"] = "default:sandstone", ["z"] = 11, ["meta"] = {["inventory"] = {}, ["fields"] = {}}}, {["y"] = 5, ["x"] = 0, ["name"] = "default:acacia_wood", ["z"] = 1, ["meta"] = {["inventory"] = {}, ["fields"] = {}}}, {["y"] = 5, ["x"] = 0, ["name"] = "default:acacia_wood", ["z"] = 2, ["meta"] = {["inventory"] = {}, ["fields"] = {}}}, {["y"] = 5, ["x"] = 0, ["name"] = "default:acacia_wood", ["z"] = 3, ["meta"] = {["inventory"] = {}, ["fields"] = {}}}, {["y"] = 5, ["x"] = 0, ["name"] = "default:acacia_wood", ["z"] = 4, ["meta"] = {["inventory"] = {}, ["fields"] = {}}}, {["y"] = 5, ["x"] = 0, ["name"] = "default:acacia_wood", ["z"] = 5, ["meta"] = {["inventory"] = {}, ["fields"] = {}}}, {["y"] = 5, ["x"] = 0, ["name"] = "default:acacia_wood", ["z"] = 6, ["meta"] = {["inventory"] = {}, ["fields"] = {}}}, {["y"] = 5, ["x"] = 0, ["name"] = "default:acacia_wood", ["z"] = 7, ["meta"] = {["inventory"] = {}, ["fields"] = {}}}, {["y"] = 5, ["x"] = 0, ["name"] = "default:acacia_wood", ["z"] = 8, ["meta"] = {["inventory"] = {}, ["fields"] = {}}}, {["y"] = 5, ["x"] = 0, ["name"] = "default:acacia_wood", ["z"] = 9, ["meta"] = {["inventory"] = {}, ["fields"] = {}}}, {["y"] = 5, ["x"] = 0, ["name"] = "default:acacia_wood", ["z"] = 10, ["meta"] = {["inventory"] = {}, ["fields"] = {}}}, {["y"] = 5, ["x"] = 0, ["name"] = "default:acacia_wood", ["z"] = 11, ["meta"] = {["inventory"] = {}, ["fields"] = {}}}, {["y"] = 6, ["x"] = 0, ["name"] = "default:acacia_wood", ["z"] = 1, ["meta"] = {["inventory"] = {}, ["fields"] = {}}}, {["y"] = 6, ["x"] = 0, ["name"] = "default:acacia_wood", ["z"] = 2, ["meta"] = {["inventory"] = {}, ["fields"] = {}}}, {["y"] = 6, ["x"] = 0, ["name"] = "default:wood", ["z"] = 3, ["meta"] = {["inventory"] = {}, ["fields"] = {}}}, {["y"] = 6, ["x"] = 0, ["name"] = "default:wood", ["z"] = 4, ["meta"] = {["inventory"] = {}, ["fields"] = {}}}, {["y"] = 6, ["x"] = 0, ["name"] = "xpanes:pane_10", ["z"] = 5, ["meta"] = {["inventory"] = {}, ["fields"] = {}}, ["param1"] = 141}, {["y"] = 6, ["x"] = 0, ["name"] = "xpanes:pane_10", ["z"] = 6, ["meta"] = {["inventory"] = {}, ["fields"] = {}}, ["param1"] = 157}, {["y"] = 6, ["x"] = 0, ["name"] = "default:wood", ["z"] = 7, ["meta"] = {["inventory"] = {}, ["fields"] = {}}}, {["y"] = 6, ["x"] = 0, ["name"] = "default:wood", ["z"] = 8, ["meta"] = {["inventory"] = {}, ["fields"] = {}}}, {["y"] = 6, ["x"] = 0, ["name"] = "default:acacia_wood", ["z"] = 9, ["meta"] = {["inventory"] = {}, ["fields"] = {}}}, {["y"] = 6, ["x"] = 0, ["name"] = "default:acacia_wood", ["z"] = 10, ["meta"] = {["inventory"] = {}, ["fields"] = {}}}, {["y"] = 6, ["x"] = 0, ["name"] = "default:acacia_wood", ["z"] = 11, ["meta"] = {["inventory"] = {}, ["fields"] = {}}}, {["y"] = 7, ["x"] = 0, ["name"] = "default:wood", ["z"] = 1, ["meta"] = {["inventory"] = {}, ["fields"] = {}}}, {["y"] = 7, ["x"] = 0, ["name"] = "default:wood", ["z"] = 2, ["meta"] = {["inventory"] = {}, ["fields"] = {}}}, {["y"] = 7, ["x"] = 0, ["name"] = "default:wood", ["z"] = 3, ["meta"] = {["inventory"] = {}, ["fields"] = {}}}, {["y"] = 7, ["x"] = 0, ["name"] = "default:wood", ["z"] = 4, ["meta"] = {["inventory"] = {}, ["fields"] = {}}}, {["y"] = 7, ["x"] = 0, ["name"] = "xpanes:pane_10", ["z"] = 5, ["meta"] = {["inventory"] = {}, ["fields"] = {}}, ["param1"] = 157}, {["y"] = 7, ["x"] = 0, ["name"] = "xpanes:pane_10", ["z"] = 6, ["meta"] = {["inventory"] = {}, ["fields"] = {}}, ["param1"] = 173}, {["y"] = 7, ["x"] = 0, ["name"] = "default:wood", ["z"] = 7, ["meta"] = {["inventory"] = {}, ["fields"] = {}}}, {["y"] = 7, ["x"] = 0, ["name"] = "default:wood", ["z"] = 8, ["meta"] = {["inventory"] = {}, ["fields"] = {}}}, {["y"] = 7, ["x"] = 0, ["name"] = "default:wood", ["z"] = 9, ["meta"] = {["inventory"] = {}, ["fields"] = {}}}, {["y"] = 7, ["x"] = 0, ["name"] = "default:wood", ["z"] = 10, ["meta"] = {["inventory"] = {}, ["fields"] = {}}}, {["y"] = 7, ["x"] = 0, ["name"] = "default:wood", ["z"] = 11, ["meta"] = {["inventory"] = {}, ["fields"] = {}}}, {["y"] = 8, ["x"] = 0, ["name"] = "default:sandstonebrick", ["z"] = 1, ["meta"] = {["inventory"] = {}, ["fields"] = {}}}, {["y"] = 8, ["x"] = 0, ["name"] = "default:sandstonebrick", ["z"] = 2, ["meta"] = {["inventory"] = {}, ["fields"] = {}}}, {["y"] = 8, ["x"] = 0, ["name"] = "default:sandstonebrick", ["z"] = 3, ["meta"] = {["inventory"] = {}, ["fields"] = {}}}, {["y"] = 8, ["x"] = 0, ["name"] = "default:sandstonebrick", ["z"] = 4, ["meta"] = {["inventory"] = {}, ["fields"] = {}}}, {["y"] = 8, ["x"] = 0, ["name"] = "default:sandstonebrick", ["z"] = 5, ["meta"] = {["inventory"] = {}, ["fields"] = {}}}, {["y"] = 8, ["x"] = 0, ["name"] = "default:sandstonebrick", ["z"] = 6, ["meta"] = {["inventory"] = {}, ["fields"] = {}}}, {["y"] = 8, ["x"] = 0, ["name"] = "default:sandstonebrick", ["z"] = 7, ["meta"] = {["inventory"] = {}, ["fields"] = {}}}, {["y"] = 8, ["x"] = 0, ["name"] = "default:sandstonebrick", ["z"] = 8, ["meta"] = {["inventory"] = {}, ["fields"] = {}}}, {["y"] = 8, ["x"] = 0, ["name"] = "default:sandstonebrick", ["z"] = 9, ["meta"] = {["inventory"] = {}, ["fields"] = {}}}, {["y"] = 8, ["x"] = 0, ["name"] = "default:sandstonebrick", ["z"] = 10, ["meta"] = {["inventory"] = {}, ["fields"] = {}}}, {["y"] = 8, ["x"] = 0, ["name"] = "default:sandstonebrick", ["z"] = 11, ["meta"] = {["inventory"] = {}, ["fields"] = {}}}, {["y"] = 9, ["x"] = 0, ["name"] = "moreblocks:panel_sandstonebrick", ["z"] = 1, ["meta"] = {["inventory"] = {}, ["fields"] = {}}, ["param1"] = 95}, {["y"] = 9, ["x"] = 0, ["name"] = "default:sandstonebrick", ["z"] = 2, ["meta"] = {["inventory"] = {}, ["fields"] = {}}}, {["y"] = 9, ["x"] = 0, ["name"] = "default:sandstonebrick", ["z"] = 3, ["meta"] = {["inventory"] = {}, ["fields"] = {}}}, {["y"] = 9, ["x"] = 0, ["name"] = "default:sandstonebrick", ["z"] = 4, ["meta"] = {["inventory"] = {}, ["fields"] = {}}}, {["y"] = 9, ["x"] = 0, ["name"] = "default:sandstonebrick", ["z"] = 5, ["meta"] = {["inventory"] = {}, ["fields"] = {}}}, {["y"] = 9, ["x"] = 0, ["name"] = "default:sandstonebrick", ["z"] = 6, ["meta"] = {["inventory"] = {}, ["fields"] = {}}}, {["y"] = 9, ["x"] = 0, ["name"] = "default:sandstonebrick", ["z"] = 7, ["meta"] = {["inventory"] = {}, ["fields"] = {}}}, {["y"] = 9, ["x"] = 0, ["name"] = "default:sandstonebrick", ["z"] = 8, ["meta"] = {["inventory"] = {}, ["fields"] = {}}}, {["y"] = 9, ["x"] = 0, ["name"] = "default:sandstonebrick", ["z"] = 9, ["meta"] = {["inventory"] = {}, ["fields"] = {}}}, {["y"] = 9, ["x"] = 0, ["name"] = "default:sandstonebrick", ["z"] = 10, ["meta"] = {["inventory"] = {}, ["fields"] = {}}}, {["y"] = 9, ["x"] = 0, ["name"] = "moreblocks:panel_sandstonebrick", ["z"] = 11, ["meta"] = {["inventory"] = {}, ["fields"] = {}}, ["param2"] = 2, ["param1"] = 95}, {["y"] = 10, ["x"] = 0, ["name"] = "moreblocks:panel_sandstonebrick", ["z"] = 2, ["meta"] = {["inventory"] = {}, ["fields"] = {}}, ["param1"] = 95}, {["y"] = 10, ["x"] = 0, ["name"] = "default:sandstonebrick", ["z"] = 3, ["meta"] = {["inventory"] = {}, ["fields"] = {}}}, {["y"] = 10, ["x"] = 0, ["name"] = "default:sandstonebrick", ["z"] = 4, ["meta"] = {["inventory"] = {}, ["fields"] = {}}}, {["y"] = 10, ["x"] = 0, ["name"] = "xpanes:pane_10", ["z"] = 5, ["meta"] = {["inventory"] = {}, ["fields"] = {}}, ["param1"] = 173}, {["y"] = 10, ["x"] = 0, ["name"] = "xpanes:pane_10", ["z"] = 6, ["meta"] = {["inventory"] = {}, ["fields"] = {}}, ["param1"] = 189}, {["y"] = 10, ["x"] = 0, ["name"] = "xpanes:pane_10", ["z"] = 7, ["meta"] = {["inventory"] = {}, ["fields"] = {}}, ["param1"] = 173}, {["y"] = 10, ["x"] = 0, ["name"] = "default:sandstonebrick", ["z"] = 8, ["meta"] = {["inventory"] = {}, ["fields"] = {}}}, {["y"] = 10, ["x"] = 0, ["name"] = "default:sandstonebrick", ["z"] = 9, ["meta"] = {["inventory"] = {}, ["fields"] = {}}}, {["y"] = 10, ["x"] = 0, ["name"] = "moreblocks:panel_sandstonebrick", ["z"] = 10, ["meta"] = {["inventory"] = {}, ["fields"] = {}}, ["param2"] = 2, ["param1"] = 95}, {["y"] = 11, ["x"] = 0, ["name"] = "moreblocks:panel_sandstonebrick", ["z"] = 3, ["meta"] = {["inventory"] = {}, ["fields"] = {}}, ["param1"] = 95}, {["y"] = 11, ["x"] = 0, ["name"] = "default:sandstonebrick", ["z"] = 4, ["meta"] = {["inventory"] = {}, ["fields"] = {}}}, {["y"] = 11, ["x"] = 0, ["name"] = "default:sandstonebrick", ["z"] = 5, ["meta"] = {["inventory"] = {}, ["fields"] = {}}}, {["y"] = 11, ["x"] = 0, ["name"] = "default:sandstonebrick", ["z"] = 6, ["meta"] = {["inventory"] = {}, ["fields"] = {}}}, {["y"] = 11, ["x"] = 0, ["name"] = "default:sandstonebrick", ["z"] = 7, ["meta"] = {["inventory"] = {}, ["fields"] = {}}}, {["y"] = 11, ["x"] = 0, ["name"] = "default:sandstonebrick", ["z"] = 8, ["meta"] = {["inventory"] = {}, ["fields"] = {}}}, {["y"] = 11, ["x"] = 0, ["name"] = "moreblocks:panel_sandstonebrick", ["z"] = 9, ["meta"] = {["inventory"] = {}, ["fields"] = {}}, ["param2"] = 2, ["param1"] = 95}, {["y"] = 12, ["x"] = 0, ["name"] = "moreblocks:panel_sandstonebrick", ["z"] = 4, ["meta"] = {["inventory"] = {}, ["fields"] = {}}, ["param1"] = 95}, {["y"] = 12, ["x"] = 0, ["name"] = "default:sandstonebrick", ["z"] = 5, ["meta"] = {["inventory"] = {}, ["fields"] = {}}}, {["y"] = 12, ["x"] = 0, ["name"] = "default:sandstonebrick", ["z"] = 6, ["meta"] = {["inventory"] = {}, ["fields"] = {}}}, {["y"] = 12, ["x"] = 0, ["name"] = "default:sandstonebrick", ["z"] = 7, ["meta"] = {["inventory"] = {}, ["fields"] = {}}}, {["y"] = 12, ["x"] = 0, ["name"] = "moreblocks:panel_sandstonebrick", ["z"] = 8, ["meta"] = {["inventory"] = {}, ["fields"] = {}}, ["param2"] = 2, ["param1"] = 95}, {["y"] = 13, ["x"] = 0, ["name"] = "moreblocks:panel_sandstonebrick", ["z"] = 5, ["meta"] = {["inventory"] = {}, ["fields"] = {}}, ["param1"] = 95}, {["y"] = 13, ["x"] = 0, ["name"] = "default:sandstonebrick", ["z"] = 6, ["meta"] = {["inventory"] = {}, ["fields"] = {}}}, {["y"] = 13, ["x"] = 0, ["name"] = "moreblocks:panel_sandstonebrick", ["z"] = 7, ["meta"] = {["inventory"] = {}, ["fields"] = {}}, ["param2"] = 2, ["param1"] = 95}, {["y"] = 0, ["x"] = 1, ["name"] = "default:dirt_with_dry_grass", ["z"] = 0, ["meta"] = {["inventory"] = {}, ["fields"] = {}}}, {["y"] = 0, ["x"] = 1, ["name"] = "default:dirt", ["z"] = 1, ["meta"] = {["inventory"] = {}, ["fields"] = {}}}, {["y"] = 0, ["x"] = 1, ["name"] = "default:stone", ["z"] = 2, ["meta"] = {["inventory"] = {}, ["fields"] = {}}}, {["y"] = 0, ["x"] = 1, ["name"] = "default:stone", ["z"] = 3, ["meta"] = {["inventory"] = {}, ["fields"] = {}}}, {["y"] = 0, ["x"] = 1, ["name"] = "default:stone", ["z"] = 4, ["meta"] = {["inventory"] = {}, ["fields"] = {}}}, {["y"] = 0, ["x"] = 1, ["name"] = "moreblocks:panel_stone", ["z"] = 5, ["meta"] = {["inventory"] = {}, ["fields"] = {}}, ["param2"] = 2, ["param1"] = 153}, {["y"] = 0, ["x"] = 1, ["name"] = "moreblocks:panel_stone", ["z"] = 8, ["meta"] = {["inventory"] = {}, ["fields"] = {}}, ["param2"] = 20, ["param1"] = 204}, {["y"] = 0, ["x"] = 1, ["name"] = "default:stone", ["z"] = 9, ["meta"] = {["inventory"] = {}, ["fields"] = {}}}, {["y"] = 0, ["x"] = 1, ["name"] = "default:stone", ["z"] = 10, ["meta"] = {["inventory"] = {}, ["fields"] = {}}}, {["y"] = 0, ["x"] = 1, ["name"] = "default:dirt", ["z"] = 11, ["meta"] = {["inventory"] = {}, ["fields"] = {}}}, {["y"] = 1, ["x"] = 1, ["name"] = "default:acacia_wood", ["z"] = 1, ["meta"] = {["inventory"] = {}, ["fields"] = {}}}, {["y"] = 1, ["x"] = 1, ["name"] = "default:furnace", ["z"] = 2, ["meta"] = {["inventory"] = {["dst"] = {"", "", "", ""}, ["src"] = {""}, ["fuel"] = {"default:wood 13"}}, ["fields"] = {["src_time"] = "0", ["fuel_totaltime"] = "0", ["infotext"] = "Furnace inactive (Item: Empty; Fuel: 0%)", ["formspec"] = "size[8,8.5]bgcolor[#080808BB;true]background[5,5;1,1;gui_formbg.png;true]listcolors[#00000069;#5A5A5A;#141318;#30434C;#FFF]list[current_name;src;2.75,0.5;1,1;]list[current_name;fuel;2.75,2.5;1,1;]image[2.75,1.5;1,1;default_furnace_fire_bg.png]image[3.75,1.5;1,1;gui_furnace_arrow_bg.png^[transformR270]list[current_name;dst;4.75,0.96;2,2;]list[current_player;main;0,4.25;8,1;]list[current_player;main;0,5.5;8,3;8]listring[current_name;dst]listring[current_player;main]listring[current_name;src]listring[current_player;main]image[0,4.25;1,1;gui_hb_bg.png]image[1,4.25;1,1;gui_hb_bg.png]image[2,4.25;1,1;gui_hb_bg.png]image[3,4.25;1,1;gui_hb_bg.png]image[4,4.25;1,1;gui_hb_bg.png]image[5,4.25;1,1;gui_hb_bg.png]image[6,4.25;1,1;gui_hb_bg.png]image[7,4.25;1,1;gui_hb_bg.png]", ["fuel_time"] = "0"}}, ["param2"] = 2}, {["y"] = 1, ["x"] = 1, ["name"] = "moreblocks:panel_acacia_wood", ["z"] = 7, ["meta"] = {["inventory"] = {}, ["fields"] = {}}, ["param2"] = 20, ["param1"] = 170}, {["y"] = 1, ["x"] = 1, ["name"] = "default:acacia_wood", ["z"] = 8, ["meta"] = {["inventory"] = {}, ["fields"] = {}}}, {["y"] = 1, ["x"] = 1, ["name"] = "moreblocks:panel_acacia_wood", ["z"] = 9, ["meta"] = {["inventory"] = {}, ["fields"] = {}}, ["param2"] = 2, ["param1"] = 170}, {["y"] = 1, ["x"] = 1, ["name"] = "default:acacia_wood", ["z"] = 11, ["meta"] = {["inventory"] = {}, ["fields"] = {}}}, {["y"] = 2, ["x"] = 1, ["name"] = "xpanes:pane_5", ["z"] = 1, ["meta"] = {["inventory"] = {}, ["fields"] = {}}, ["param1"] = 189}, {["y"] = 2, ["x"] = 1, ["name"] = "moreblocks:panel_acacia_wood", ["z"] = 6, ["meta"] = {["inventory"] = {}, ["fields"] = {}}, ["param2"] = 20, ["param1"] = 136}, {["y"] = 2, ["x"] = 1, ["name"] = "default:acacia_wood", ["z"] = 7, ["meta"] = {["inventory"] = {}, ["fields"] = {}}}, {["y"] = 2, ["x"] = 1, ["name"] = "moreblocks:panel_acacia_wood", ["z"] = 8, ["meta"] = {["inventory"] = {}, ["fields"] = {}}, ["param2"] = 2, ["param1"] = 170}, {["y"] = 2, ["x"] = 1, ["name"] = "default:acacia_wood", ["z"] = 11, ["meta"] = {["inventory"] = {}, ["fields"] = {}}}, {["y"] = 3, ["x"] = 1, ["name"] = "default:wood", ["z"] = 1, ["meta"] = {["inventory"] = {}, ["fields"] = {}}}, {["y"] = 3, ["x"] = 1, ["name"] = "homedecor:glowlight_small_cube_white", ["z"] = 2, ["meta"] = {["inventory"] = {}, ["fields"] = {}}, ["param2"] = 12}, {["y"] = 3, ["x"] = 1, ["name"] = "moreblocks:panel_wood", ["z"] = 5, ["meta"] = {["inventory"] = {}, ["fields"] = {}}, ["param2"] = 20, ["param1"] = 170}, {["y"] = 3, ["x"] = 1, ["name"] = "default:wood", ["z"] = 6, ["meta"] = {["inventory"] = {}, ["fields"] = {}}}, {["y"] = 3, ["x"] = 1, ["name"] = "moreblocks:panel_wood", ["z"] = 7, ["meta"] = {["inventory"] = {}, ["fields"] = {}}, ["param2"] = 2, ["param1"] = 170}, {["y"] = 3, ["x"] = 1, ["name"] = "homedecor:glowlight_small_cube_white", ["z"] = 10, ["meta"] = {["inventory"] = {}, ["fields"] = {}}, ["param2"] = 12}, {["y"] = 3, ["x"] = 1, ["name"] = "default:wood", ["z"] = 11, ["meta"] = {["inventory"] = {}, ["fields"] = {}}}, {["y"] = 4, ["x"] = 1, ["name"] = "default:sandstone", ["z"] = 1, ["meta"] = {["inventory"] = {}, ["fields"] = {}}}, {["y"] = 4, ["x"] = 1, ["name"] = "default:sandstone", ["z"] = 2, ["meta"] = {["inventory"] = {}, ["fields"] = {}}}, {["y"] = 4, ["x"] = 1, ["name"] = "default:sandstone", ["z"] = 3, ["meta"] = {["inventory"] = {}, ["fields"] = {}}}, {["y"] = 4, ["x"] = 1, ["name"] = "default:sandstone", ["z"] = 4, ["meta"] = {["inventory"] = {}, ["fields"] = {}}}, {["y"] = 4, ["x"] = 1, ["name"] = "default:sandstone", ["z"] = 5, ["meta"] = {["inventory"] = {}, ["fields"] = {}}}, {["y"] = 4, ["x"] = 1, ["name"] = "moreblocks:panel_sandstone", ["z"] = 6, ["meta"] = {["inventory"] = {}, ["fields"] = {}}, ["param2"] = 2, ["param1"] = 138}, {["y"] = 4, ["x"] = 1, ["name"] = "default:sandstone", ["z"] = 11, ["meta"] = {["inventory"] = {}, ["fields"] = {}}}, {["y"] = 5, ["x"] = 1, ["name"] = "default:acacia_wood", ["z"] = 1, ["meta"] = {["inventory"] = {}, ["fields"] = {}}}, {["y"] = 5, ["x"] = 1, ["name"] = "default:acacia_wood", ["z"] = 11, ["meta"] = {["inventory"] = {}, ["fields"] = {}}}, {["y"] = 6, ["x"] = 1, ["name"] = "default:acacia_wood", ["z"] = 1, ["meta"] = {["inventory"] = {}, ["fields"] = {}}}, {["y"] = 6, ["x"] = 1, ["name"] = "xpanes:pane_5", ["z"] = 11, ["meta"] = {["inventory"] = {}, ["fields"] = {}}, ["param1"] = 157}, {["y"] = 7, ["x"] = 1, ["name"] = "default:wood", ["z"] = 1, ["meta"] = {["inventory"] = {}, ["fields"] = {}}}, {["y"] = 7, ["x"] = 1, ["name"] = "homedecor:glowlight_small_cube_white", ["z"] = 2, ["meta"] = {["inventory"] = {}, ["fields"] = {}}, ["param2"] = 22}, {["y"] = 7, ["x"] = 1, ["name"] = "homedecor:glowlight_small_cube_white", ["z"] = 8, ["meta"] = {["inventory"] = {}, ["fields"] = {}}, ["param2"] = 20}, {["y"] = 7, ["x"] = 1, ["name"] = "xpanes:pane_5", ["z"] = 11, ["meta"] = {["inventory"] = {}, ["fields"] = {}}, ["param1"] = 173}, {["y"] = 8, ["x"] = 1, ["name"] = "default:sandstonebrick", ["z"] = 1, ["meta"] = {["inventory"] = {}, ["fields"] = {}}}, {["y"] = 8, ["x"] = 1, ["name"] = "default:sandstonebrick", ["z"] = 2, ["meta"] = {["inventory"] = {}, ["fields"] = {}}}, {["y"] = 8, ["x"] = 1, ["name"] = "default:sandstonebrick", ["z"] = 3, ["meta"] = {["inventory"] = {}, ["fields"] = {}}}, {["y"] = 8, ["x"] = 1, ["name"] = "default:sandstonebrick", ["z"] = 4, ["meta"] = {["inventory"] = {}, ["fields"] = {}}}, {["y"] = 8, ["x"] = 1, ["name"] = "default:sandstonebrick", ["z"] = 5, ["meta"] = {["inventory"] = {}, ["fields"] = {}}}, {["y"] = 8, ["x"] = 1, ["name"] = "default:sandstonebrick", ["z"] = 6, ["meta"] = {["inventory"] = {}, ["fields"] = {}}}, {["y"] = 8, ["x"] = 1, ["name"] = "default:sandstonebrick", ["z"] = 7, ["meta"] = {["inventory"] = {}, ["fields"] = {}}}, {["y"] = 8, ["x"] = 1, ["name"] = "default:sandstonebrick", ["z"] = 8, ["meta"] = {["inventory"] = {}, ["fields"] = {}}}, {["y"] = 8, ["x"] = 1, ["name"] = "default:sandstonebrick", ["z"] = 9, ["meta"] = {["inventory"] = {}, ["fields"] = {}}}, {["y"] = 8, ["x"] = 1, ["name"] = "default:sandstonebrick", ["z"] = 10, ["meta"] = {["inventory"] = {}, ["fields"] = {}}}, {["y"] = 8, ["x"] = 1, ["name"] = "default:sandstonebrick", ["z"] = 11, ["meta"] = {["inventory"] = {}, ["fields"] = {}}}, {["y"] = 9, ["x"] = 1, ["name"] = "moreblocks:panel_sandstonebrick", ["z"] = 1, ["meta"] = {["inventory"] = {}, ["fields"] = {}}, ["param1"] = 111}, {["y"] = 9, ["x"] = 1, ["name"] = "default:sandstonebrick", ["z"] = 2, ["meta"] = {["inventory"] = {}, ["fields"] = {}}}, {["y"] = 9, ["x"] = 1, ["name"] = "torches:floor", ["z"] = 3, ["meta"] = {["inventory"] = {}, ["fields"] = {}}, ["param2"] = 1}, {["y"] = 9, ["x"] = 1, ["name"] = "torches:floor", ["z"] = 9, ["meta"] = {["inventory"] = {}, ["fields"] = {}}, ["param2"] = 1}, {["y"] = 9, ["x"] = 1, ["name"] = "default:sandstonebrick", ["z"] = 10, ["meta"] = {["inventory"] = {}, ["fields"] = {}}}, {["y"] = 9, ["x"] = 1, ["name"] = "moreblocks:panel_sandstonebrick", ["z"] = 11, ["meta"] = {["inventory"] = {}, ["fields"] = {}}, ["param2"] = 2, ["param1"] = 111}, {["y"] = 10, ["x"] = 1, ["name"] = "moreblocks:panel_sandstonebrick", ["z"] = 2, ["meta"] = {["inventory"] = {}, ["fields"] = {}}, ["param1"] = 79}, {["y"] = 10, ["x"] = 1, ["name"] = "default:sandstonebrick", ["z"] = 3, ["meta"] = {["inventory"] = {}, ["fields"] = {}}}, {["y"] = 10, ["x"] = 1, ["name"] = "default:sandstonebrick", ["z"] = 9, ["meta"] = {["inventory"] = {}, ["fields"] = {}}}, {["y"] = 10, ["x"] = 1, ["name"] = "moreblocks:panel_sandstonebrick", ["z"] = 10, ["meta"] = {["inventory"] = {}, ["fields"] = {}}, ["param2"] = 2, ["param1"] = 79}, {["y"] = 11, ["x"] = 1, ["name"] = "moreblocks:panel_sandstonebrick", ["z"] = 3, ["meta"] = {["inventory"] = {}, ["fields"] = {}}, ["param1"] = 79}, {["y"] = 11, ["x"] = 1, ["name"] = "default:sandstonebrick", ["z"] = 4, ["meta"] = {["inventory"] = {}, ["fields"] = {}}}, {["y"] = 11, ["x"] = 1, ["name"] = "torches:wall", ["z"] = 6, ["meta"] = {["inventory"] = {}, ["fields"] = {}}, ["param2"] = 3}, {["y"] = 11, ["x"] = 1, ["name"] = "default:sandstonebrick", ["z"] = 8, ["meta"] = {["inventory"] = {}, ["fields"] = {}}}, {["y"] = 11, ["x"] = 1, ["name"] = "moreblocks:panel_sandstonebrick", ["z"] = 9, ["meta"] = {["inventory"] = {}, ["fields"] = {}}, ["param2"] = 2, ["param1"] = 79}, {["y"] = 12, ["x"] = 1, ["name"] = "moreblocks:panel_sandstonebrick", ["z"] = 4, ["meta"] = {["inventory"] = {}, ["fields"] = {}}, ["param1"] = 79}, {["y"] = 12, ["x"] = 1, ["name"] = "default:sandstonebrick", ["z"] = 5, ["meta"] = {["inventory"] = {}, ["fields"] = {}}}, {["y"] = 12, ["x"] = 1, ["name"] = "default:sandstonebrick", ["z"] = 7, ["meta"] = {["inventory"] = {}, ["fields"] = {}}}, {["y"] = 12, ["x"] = 1, ["name"] = "moreblocks:panel_sandstonebrick", ["z"] = 8, ["meta"] = {["inventory"] = {}, ["fields"] = {}}, ["param2"] = 2, ["param1"] = 79}, {["y"] = 13, ["x"] = 1, ["name"] = "moreblocks:panel_sandstonebrick", ["z"] = 5, ["meta"] = {["inventory"] = {}, ["fields"] = {}}, ["param1"] = 79}, {["y"] = 13, ["x"] = 1, ["name"] = "default:sandstonebrick", ["z"] = 6, ["meta"] = {["inventory"] = {}, ["fields"] = {}}}, {["y"] = 13, ["x"] = 1, ["name"] = "moreblocks:panel_sandstonebrick", ["z"] = 7, ["meta"] = {["inventory"] = {}, ["fields"] = {}}, ["param2"] = 2, ["param1"] = 79}, {["y"] = 0, ["x"] = 2, ["name"] = "default:dirt_with_grass", ["z"] = 0, ["meta"] = {["inventory"] = {}, ["fields"] = {}}}, {["y"] = 0, ["x"] = 2, ["name"] = "default:dirt", ["z"] = 1, ["meta"] = {["inventory"] = {}, ["fields"] = {}}}, {["y"] = 0, ["x"] = 2, ["name"] = "default:stone", ["z"] = 2, ["meta"] = {["inventory"] = {}, ["fields"] = {}}}, {["y"] = 0, ["x"] = 2, ["name"] = "default:stone", ["z"] = 3, ["meta"] = {["inventory"] = {}, ["fields"] = {}}}, {["y"] = 0, ["x"] = 2, ["name"] = "default:stone", ["z"] = 4, ["meta"] = {["inventory"] = {}, ["fields"] = {}}}, {["y"] = 0, ["x"] = 2, ["name"] = "moreblocks:panel_stone", ["z"] = 5, ["meta"] = {["inventory"] = {}, ["fields"] = {}}, ["param2"] = 2, ["param1"] = 136}, {["y"] = 0, ["x"] = 2, ["name"] = "moreblocks:panel_stone", ["z"] = 8, ["meta"] = {["inventory"] = {}, ["fields"] = {}}, ["param2"] = 20, ["param1"] = 187}, {["y"] = 0, ["x"] = 2, ["name"] = "default:stone", ["z"] = 9, ["meta"] = {["inventory"] = {}, ["fields"] = {}}}, {["y"] = 0, ["x"] = 2, ["name"] = "default:stone", ["z"] = 10, ["meta"] = {["inventory"] = {}, ["fields"] = {}}}, {["y"] = 0, ["x"] = 2, ["name"] = "default:dirt", ["z"] = 11, ["meta"] = {["inventory"] = {}, ["fields"] = {}}}, {["y"] = 1, ["x"] = 2, ["name"] = "default:acacia_wood", ["z"] = 1, ["meta"] = {["inventory"] = {}, ["fields"] = {}}}, {["y"] = 1, ["x"] = 2, ["name"] = "default:chest", ["z"] = 2, ["meta"] = {["inventory"] = {["main"] = {"", "", "", "", "", "", "", "", "", "", "", "", "", "", "", "", "", "", "", "", "", "", "", "", "", "", "", "", "", "", "", ""}}, ["fields"] = {["formspec"] = "size[8,9]bgcolor[#080808BB;true]background[5,5;1,1;gui_formbg.png;true]listcolors[#00000069;#5A5A5A;#141318;#30434C;#FFF]list[current_name;main;0,0.3;8,4;]list[current_player;main;0,4.85;8,1;]list[current_player;main;0,6.08;8,3;8]listring[current_name;main]listring[current_player;main]image[0,4.85;1,1;gui_hb_bg.png]image[1,4.85;1,1;gui_hb_bg.png]image[2,4.85;1,1;gui_hb_bg.png]image[3,4.85;1,1;gui_hb_bg.png]image[4,4.85;1,1;gui_hb_bg.png]image[5,4.85;1,1;gui_hb_bg.png]image[6,4.85;1,1;gui_hb_bg.png]image[7,4.85;1,1;gui_hb_bg.png]", ["infotext"] = "Chest"}}, ["param2"] = 2}, {["y"] = 1, ["x"] = 2, ["name"] = "moreblocks:panel_acacia_wood", ["z"] = 7, ["meta"] = {["inventory"] = {}, ["fields"] = {}}, ["param2"] = 20, ["param1"] = 153}, {["y"] = 1, ["x"] = 2, ["name"] = "default:acacia_wood", ["z"] = 8, ["meta"] = {["inventory"] = {}, ["fields"] = {}}}, {["y"] = 1, ["x"] = 2, ["name"] = "moreblocks:panel_acacia_wood", ["z"] = 9, ["meta"] = {["inventory"] = {}, ["fields"] = {}}, ["param2"] = 2, ["param1"] = 154}, {["y"] = 1, ["x"] = 2, ["name"] = "default:acacia_wood", ["z"] = 11, ["meta"] = {["inventory"] = {}, ["fields"] = {}}}, {["y"] = 2, ["x"] = 2, ["name"] = "xpanes:pane_5", ["z"] = 1, ["meta"] = {["inventory"] = {}, ["fields"] = {}}, ["param1"] = 173}, {["y"] = 2, ["x"] = 2, ["name"] = "moreblocks:panel_acacia_wood", ["z"] = 6, ["meta"] = {["inventory"] = {}, ["fields"] = {}}, ["param2"] = 20, ["param1"] = 153}, {["y"] = 2, ["x"] = 2, ["name"] = "default:acacia_wood", ["z"] = 7, ["meta"] = {["inventory"] = {}, ["fields"] = {}}}, {["y"] = 2, ["x"] = 2, ["name"] = "moreblocks:panel_acacia_wood", ["z"] = 8, ["meta"] = {["inventory"] = {}, ["fields"] = {}}, ["param2"] = 2, ["param1"] = 154}, {["y"] = 2, ["x"] = 2, ["name"] = "xpanes:pane_5", ["z"] = 11, ["meta"] = {["inventory"] = {}, ["fields"] = {}}, ["param1"] = 173}, {["y"] = 3, ["x"] = 2, ["name"] = "default:wood", ["z"] = 1, ["meta"] = {["inventory"] = {}, ["fields"] = {}}}, {["y"] = 3, ["x"] = 2, ["name"] = "moreblocks:panel_wood", ["z"] = 5, ["meta"] = {["inventory"] = {}, ["fields"] = {}}, ["param2"] = 20, ["param1"] = 153}, {["y"] = 3, ["x"] = 2, ["name"] = "default:wood", ["z"] = 6, ["meta"] = {["inventory"] = {}, ["fields"] = {}}}, {["y"] = 3, ["x"] = 2, ["name"] = "moreblocks:panel_wood", ["z"] = 7, ["meta"] = {["inventory"] = {}, ["fields"] = {}}, ["param2"] = 2, ["param1"] = 153}, {["y"] = 3, ["x"] = 2, ["name"] = "default:wood", ["z"] = 11, ["meta"] = {["inventory"] = {}, ["fields"] = {}}}, {["y"] = 4, ["x"] = 2, ["name"] = "default:sandstone", ["z"] = 1, ["meta"] = {["inventory"] = {}, ["fields"] = {}}}, {["y"] = 4, ["x"] = 2, ["name"] = "default:sandstone", ["z"] = 2, ["meta"] = {["inventory"] = {}, ["fields"] = {}}}, {["y"] = 4, ["x"] = 2, ["name"] = "default:sandstone", ["z"] = 3, ["meta"] = {["inventory"] = {}, ["fields"] = {}}}, {["y"] = 4, ["x"] = 2, ["name"] = "default:sandstone", ["z"] = 4, ["meta"] = {["inventory"] = {}, ["fields"] = {}}}, {["y"] = 4, ["x"] = 2, ["name"] = "default:sandstone", ["z"] = 5, ["meta"] = {["inventory"] = {}, ["fields"] = {}}}, {["y"] = 4, ["x"] = 2, ["name"] = "moreblocks:panel_sandstone", ["z"] = 6, ["meta"] = {["inventory"] = {}, ["fields"] = {}}, ["param2"] = 2, ["param1"] = 121}, {["y"] = 4, ["x"] = 2, ["name"] = "default:sandstone", ["z"] = 11, ["meta"] = {["inventory"] = {}, ["fields"] = {}}}, {["y"] = 5, ["x"] = 2, ["name"] = "default:acacia_wood", ["z"] = 1, ["meta"] = {["inventory"] = {}, ["fields"] = {}}}, {["y"] = 5, ["x"] = 2, ["name"] = "default:ladder_wood", ["z"] = 5, ["meta"] = {["inventory"] = {}, ["fields"] = {}}, ["param2"] = 2, ["param1"] = 122}, {["y"] = 5, ["x"] = 2, ["name"] = "default:acacia_wood", ["z"] = 11, ["meta"] = {["inventory"] = {}, ["fields"] = {}}}, {["y"] = 6, ["x"] = 2, ["name"] = "xpanes:pane_5", ["z"] = 1, ["meta"] = {["inventory"] = {}, ["fields"] = {}}, ["param1"] = 173}, {["y"] = 6, ["x"] = 2, ["name"] = "default:ladder_wood", ["z"] = 5, ["meta"] = {["inventory"] = {}, ["fields"] = {}}, ["param2"] = 2, ["param1"] = 139}, {["y"] = 6, ["x"] = 2, ["name"] = "xpanes:pane_5", ["z"] = 11, ["meta"] = {["inventory"] = {}, ["fields"] = {}}, ["param1"] = 141}, {["y"] = 7, ["x"] = 2, ["name"] = "xpanes:pane_5", ["z"] = 1, ["meta"] = {["inventory"] = {}, ["fields"] = {}}, ["param1"] = 189}, {["y"] = 7, ["x"] = 2, ["name"] = "default:ladder_wood", ["z"] = 5, ["meta"] = {["inventory"] = {}, ["fields"] = {}}, ["param2"] = 2, ["param1"] = 155}, {["y"] = 7, ["x"] = 2, ["name"] = "xpanes:pane_5", ["z"] = 11, ["meta"] = {["inventory"] = {}, ["fields"] = {}}, ["param1"] = 157}, {["y"] = 8, ["x"] = 2, ["name"] = "default:sandstonebrick", ["z"] = 1, ["meta"] = {["inventory"] = {}, ["fields"] = {}}}, {["y"] = 8, ["x"] = 2, ["name"] = "default:sandstonebrick", ["z"] = 2, ["meta"] = {["inventory"] = {}, ["fields"] = {}}}, {["y"] = 8, ["x"] = 2, ["name"] = "default:sandstonebrick", ["z"] = 3, ["meta"] = {["inventory"] = {}, ["fields"] = {}}}, {["y"] = 8, ["x"] = 2, ["name"] = "default:sandstonebrick", ["z"] = 4, ["meta"] = {["inventory"] = {}, ["fields"] = {}}}, {["y"] = 8, ["x"] = 2, ["name"] = "default:ladder_wood", ["z"] = 5, ["meta"] = {["inventory"] = {}, ["fields"] = {}}, ["param2"] = 2, ["param1"] = 154}, {["y"] = 8, ["x"] = 2, ["name"] = "default:sandstonebrick", ["z"] = 6, ["meta"] = {["inventory"] = {}, ["fields"] = {}}}, {["y"] = 8, ["x"] = 2, ["name"] = "default:sandstonebrick", ["z"] = 7, ["meta"] = {["inventory"] = {}, ["fields"] = {}}}, {["y"] = 8, ["x"] = 2, ["name"] = "default:sandstonebrick", ["z"] = 8, ["meta"] = {["inventory"] = {}, ["fields"] = {}}}, {["y"] = 8, ["x"] = 2, ["name"] = "default:sandstonebrick", ["z"] = 9, ["meta"] = {["inventory"] = {}, ["fields"] = {}}}, {["y"] = 8, ["x"] = 2, ["name"] = "default:sandstonebrick", ["z"] = 10, ["meta"] = {["inventory"] = {}, ["fields"] = {}}}, {["y"] = 8, ["x"] = 2, ["name"] = "default:sandstonebrick", ["z"] = 11, ["meta"] = {["inventory"] = {}, ["fields"] = {}}}, {["y"] = 9, ["x"] = 2, ["name"] = "moreblocks:panel_sandstonebrick", ["z"] = 1, ["meta"] = {["inventory"] = {}, ["fields"] = {}}, ["param1"] = 127}, {["y"] = 9, ["x"] = 2, ["name"] = "default:sandstonebrick", ["z"] = 2, ["meta"] = {["inventory"] = {}, ["fields"] = {}}}, {["y"] = 9, ["x"] = 2, ["name"] = "default:sandstonebrick", ["z"] = 10, ["meta"] = {["inventory"] = {}, ["fields"] = {}}}, {["y"] = 9, ["x"] = 2, ["name"] = "moreblocks:panel_sandstonebrick", ["z"] = 11, ["meta"] = {["inventory"] = {}, ["fields"] = {}}, ["param2"] = 2, ["param1"] = 95}, {["y"] = 10, ["x"] = 2, ["name"] = "moreblocks:panel_sandstonebrick", ["z"] = 2, ["meta"] = {["inventory"] = {}, ["fields"] = {}}, ["param1"] = 95}, {["y"] = 10, ["x"] = 2, ["name"] = "default:sandstonebrick", ["z"] = 3, ["meta"] = {["inventory"] = {}, ["fields"] = {}}}, {["y"] = 10, ["x"] = 2, ["name"] = "default:sandstonebrick", ["z"] = 9, ["meta"] = {["inventory"] = {}, ["fields"] = {}}}, {["y"] = 10, ["x"] = 2, ["name"] = "moreblocks:panel_sandstonebrick", ["z"] = 10, ["meta"] = {["inventory"] = {}, ["fields"] = {}}, ["param2"] = 2, ["param1"] = 63}, {["y"] = 11, ["x"] = 2, ["name"] = "moreblocks:panel_sandstonebrick", ["z"] = 3, ["meta"] = {["inventory"] = {}, ["fields"] = {}}, ["param1"] = 63}, {["y"] = 11, ["x"] = 2, ["name"] = "default:sandstonebrick", ["z"] = 4, ["meta"] = {["inventory"] = {}, ["fields"] = {}}}, {["y"] = 11, ["x"] = 2, ["name"] = "default:sandstonebrick", ["z"] = 8, ["meta"] = {["inventory"] = {}, ["fields"] = {}}}, {["y"] = 11, ["x"] = 2, ["name"] = "moreblocks:panel_sandstonebrick", ["z"] = 9, ["meta"] = {["inventory"] = {}, ["fields"] = {}}, ["param2"] = 2, ["param1"] = 63}, {["y"] = 12, ["x"] = 2, ["name"] = "moreblocks:panel_sandstonebrick", ["z"] = 4, ["meta"] = {["inventory"] = {}, ["fields"] = {}}, ["param1"] = 63}, {["y"] = 12, ["x"] = 2, ["name"] = "default:sandstonebrick", ["z"] = 5, ["meta"] = {["inventory"] = {}, ["fields"] = {}}}, {["y"] = 12, ["x"] = 2, ["name"] = "default:sandstonebrick", ["z"] = 7, ["meta"] = {["inventory"] = {}, ["fields"] = {}}}, {["y"] = 12, ["x"] = 2, ["name"] = "moreblocks:panel_sandstonebrick", ["z"] = 8, ["meta"] = {["inventory"] = {}, ["fields"] = {}}, ["param2"] = 2, ["param1"] = 63}, {["y"] = 13, ["x"] = 2, ["name"] = "moreblocks:panel_sandstonebrick", ["z"] = 5, ["meta"] = {["inventory"] = {}, ["fields"] = {}}, ["param1"] = 63}, {["y"] = 13, ["x"] = 2, ["name"] = "default:sandstonebrick", ["z"] = 6, ["meta"] = {["inventory"] = {}, ["fields"] = {}}}, {["y"] = 13, ["x"] = 2, ["name"] = "moreblocks:panel_sandstonebrick", ["z"] = 7, ["meta"] = {["inventory"] = {}, ["fields"] = {}}, ["param2"] = 2, ["param1"] = 63}, {["y"] = 0, ["x"] = 3, ["name"] = "default:dirt_with_grass", ["z"] = 0, ["meta"] = {["inventory"] = {}, ["fields"] = {}}}, {["y"] = 0, ["x"] = 3, ["name"] = "default:dirt", ["z"] = 1, ["meta"] = {["inventory"] = {}, ["fields"] = {}}}, {["y"] = 0, ["x"] = 3, ["name"] = "default:stone", ["z"] = 2, ["meta"] = {["inventory"] = {}, ["fields"] = {}}}, {["y"] = 0, ["x"] = 3, ["name"] = "default:stone", ["z"] = 3, ["meta"] = {["inventory"] = {}, ["fields"] = {}}}, {["y"] = 0, ["x"] = 3, ["name"] = "default:stone", ["z"] = 4, ["meta"] = {["inventory"] = {}, ["fields"] = {}}}, {["y"] = 0, ["x"] = 3, ["name"] = "default:stone", ["z"] = 5, ["meta"] = {["inventory"] = {}, ["fields"] = {}}}, {["y"] = 0, ["x"] = 3, ["name"] = "default:stone", ["z"] = 6, ["meta"] = {["inventory"] = {}, ["fields"] = {}}}, {["y"] = 0, ["x"] = 3, ["name"] = "default:stone", ["z"] = 7, ["meta"] = {["inventory"] = {}, ["fields"] = {}}}, {["y"] = 0, ["x"] = 3, ["name"] = "default:stone", ["z"] = 8, ["meta"] = {["inventory"] = {}, ["fields"] = {}}}, {["y"] = 0, ["x"] = 3, ["name"] = "default:stone", ["z"] = 9, ["meta"] = {["inventory"] = {}, ["fields"] = {}}}, {["y"] = 0, ["x"] = 3, ["name"] = "default:stone", ["z"] = 10, ["meta"] = {["inventory"] = {}, ["fields"] = {}}}, {["y"] = 0, ["x"] = 3, ["name"] = "default:dirt", ["z"] = 11, ["meta"] = {["inventory"] = {}, ["fields"] = {}}}, {["y"] = 1, ["x"] = 3, ["name"] = "default:acacia_wood", ["z"] = 1, ["meta"] = {["inventory"] = {}, ["fields"] = {}}}, {["y"] = 1, ["x"] = 3, ["name"] = "default:fence_acacia_wood", ["z"] = 5, ["meta"] = {["inventory"] = {}, ["fields"] = {}}, ["param1"] = 136}, {["y"] = 1, ["x"] = 3, ["name"] = "default:fence_acacia_wood", ["z"] = 6, ["meta"] = {["inventory"] = {}, ["fields"] = {}}, ["param1"] = 153}, {["y"] = 1, ["x"] = 3, ["name"] = "default:fence_acacia_wood", ["z"] = 7, ["meta"] = {["inventory"] = {}, ["fields"] = {}}, ["param1"] = 136}, {["y"] = 1, ["x"] = 3, ["name"] = "default:fence_acacia_wood", ["z"] = 8, ["meta"] = {["inventory"] = {}, ["fields"] = {}}, ["param1"] = 121}, {["y"] = 1, ["x"] = 3, ["name"] = "default:acacia_wood", ["z"] = 11, ["meta"] = {["inventory"] = {}, ["fields"] = {}}}, {["y"] = 2, ["x"] = 3, ["name"] = "xpanes:pane_5", ["z"] = 1, ["meta"] = {["inventory"] = {}, ["fields"] = {}}, ["param1"] = 157}, {["y"] = 2, ["x"] = 3, ["name"] = "default:fence_acacia_wood", ["z"] = 5, ["meta"] = {["inventory"] = {}, ["fields"] = {}}, ["param1"] = 153}, {["y"] = 2, ["x"] = 3, ["name"] = "default:fence_acacia_wood", ["z"] = 6, ["meta"] = {["inventory"] = {}, ["fields"] = {}}, ["param1"] = 170}, {["y"] = 2, ["x"] = 3, ["name"] = "default:fence_acacia_wood", ["z"] = 7, ["meta"] = {["inventory"] = {}, ["fields"] = {}}, ["param1"] = 153}, {["y"] = 2, ["x"] = 3, ["name"] = "default:fence_acacia_wood", ["z"] = 8, ["meta"] = {["inventory"] = {}, ["fields"] = {}}, ["param1"] = 138}, {["y"] = 2, ["x"] = 3, ["name"] = "xpanes:pane_5", ["z"] = 11, ["meta"] = {["inventory"] = {}, ["fields"] = {}}, ["param1"] = 157}, {["y"] = 3, ["x"] = 3, ["name"] = "default:wood", ["z"] = 1, ["meta"] = {["inventory"] = {}, ["fields"] = {}}}, {["y"] = 3, ["x"] = 3, ["name"] = "default:fence_wood", ["z"] = 5, ["meta"] = {["inventory"] = {}, ["fields"] = {}}, ["param1"] = 170}, {["y"] = 3, ["x"] = 3, ["name"] = "default:fence_wood", ["z"] = 6, ["meta"] = {["inventory"] = {}, ["fields"] = {}}, ["param1"] = 187}, {["y"] = 3, ["x"] = 3, ["name"] = "default:fence_wood", ["z"] = 7, ["meta"] = {["inventory"] = {}, ["fields"] = {}}, ["param1"] = 170}, {["y"] = 3, ["x"] = 3, ["name"] = "default:fence_wood", ["z"] = 8, ["meta"] = {["inventory"] = {}, ["fields"] = {}}, ["param1"] = 153}, {["y"] = 3, ["x"] = 3, ["name"] = "default:wood", ["z"] = 11, ["meta"] = {["inventory"] = {}, ["fields"] = {}}}, {["y"] = 4, ["x"] = 3, ["name"] = "default:sandstone", ["z"] = 1, ["meta"] = {["inventory"] = {}, ["fields"] = {}}}, {["y"] = 4, ["x"] = 3, ["name"] = "default:sandstone", ["z"] = 2, ["meta"] = {["inventory"] = {}, ["fields"] = {}}}, {["y"] = 4, ["x"] = 3, ["name"] = "default:sandstone", ["z"] = 3, ["meta"] = {["inventory"] = {}, ["fields"] = {}}}, {["y"] = 4, ["x"] = 3, ["name"] = "default:sandstone", ["z"] = 4, ["meta"] = {["inventory"] = {}, ["fields"] = {}}}, {["y"] = 4, ["x"] = 3, ["name"] = "default:sandstone", ["z"] = 5, ["meta"] = {["inventory"] = {}, ["fields"] = {}}}, {["y"] = 4, ["x"] = 3, ["name"] = "default:sandstone", ["z"] = 6, ["meta"] = {["inventory"] = {}, ["fields"] = {}}}, {["y"] = 4, ["x"] = 3, ["name"] = "default:sandstone", ["z"] = 7, ["meta"] = {["inventory"] = {}, ["fields"] = {}}}, {["y"] = 4, ["x"] = 3, ["name"] = "default:sandstone", ["z"] = 8, ["meta"] = {["inventory"] = {}, ["fields"] = {}}}, {["y"] = 4, ["x"] = 3, ["name"] = "default:sandstone", ["z"] = 9, ["meta"] = {["inventory"] = {}, ["fields"] = {}}}, {["y"] = 4, ["x"] = 3, ["name"] = "default:sandstone", ["z"] = 10, ["meta"] = {["inventory"] = {}, ["fields"] = {}}}, {["y"] = 4, ["x"] = 3, ["name"] = "default:sandstone", ["z"] = 11, ["meta"] = {["inventory"] = {}, ["fields"] = {}}}, {["y"] = 5, ["x"] = 3, ["name"] = "default:acacia_wood", ["z"] = 1, ["meta"] = {["inventory"] = {}, ["fields"] = {}}}, {["y"] = 5, ["x"] = 3, ["name"] = "default:acacia_wood", ["z"] = 5, ["meta"] = {["inventory"] = {}, ["fields"] = {}}}, {["y"] = 5, ["x"] = 3, ["name"] = "default:acacia_wood", ["z"] = 6, ["meta"] = {["inventory"] = {}, ["fields"] = {}}}, {["y"] = 5, ["x"] = 3, ["name"] = "default:acacia_wood", ["z"] = 7, ["meta"] = {["inventory"] = {}, ["fields"] = {}}}, {["y"] = 5, ["x"] = 3, ["name"] = "default:acacia_wood", ["z"] = 8, ["meta"] = {["inventory"] = {}, ["fields"] = {}}}, {["y"] = 5, ["x"] = 3, ["name"] = "default:acacia_wood", ["z"] = 9, ["meta"] = {["inventory"] = {}, ["fields"] = {}}}, {["y"] = 5, ["x"] = 3, ["name"] = "default:acacia_wood", ["z"] = 10, ["meta"] = {["inventory"] = {}, ["fields"] = {}}}, {["y"] = 5, ["x"] = 3, ["name"] = "default:acacia_wood", ["z"] = 11, ["meta"] = {["inventory"] = {}, ["fields"] = {}}}, {["y"] = 6, ["x"] = 3, ["name"] = "xpanes:pane_5", ["z"] = 1, ["meta"] = {["inventory"] = {}, ["fields"] = {}}, ["param1"] = 157}, {["y"] = 6, ["x"] = 3, ["name"] = "default:acacia_wood", ["z"] = 5, ["meta"] = {["inventory"] = {}, ["fields"] = {}}}, {["y"] = 6, ["x"] = 3, ["name"] = "default:acacia_wood", ["z"] = 6, ["meta"] = {["inventory"] = {}, ["fields"] = {}}}, {["y"] = 6, ["x"] = 3, ["name"] = "default:wood", ["z"] = 7, ["meta"] = {["inventory"] = {}, ["fields"] = {}}}, {["y"] = 6, ["x"] = 3, ["name"] = "default:wood", ["z"] = 8, ["meta"] = {["inventory"] = {}, ["fields"] = {}}}, {["y"] = 6, ["x"] = 3, ["name"] = "default:acacia_wood", ["z"] = 9, ["meta"] = {["inventory"] = {}, ["fields"] = {}}}, {["y"] = 6, ["x"] = 3, ["name"] = "default:acacia_wood", ["z"] = 10, ["meta"] = {["inventory"] = {}, ["fields"] = {}}}, {["y"] = 6, ["x"] = 3, ["name"] = "default:acacia_wood", ["z"] = 11, ["meta"] = {["inventory"] = {}, ["fields"] = {}}}, {["y"] = 7, ["x"] = 3, ["name"] = "xpanes:pane_5", ["z"] = 1, ["meta"] = {["inventory"] = {}, ["fields"] = {}}, ["param1"] = 173}, {["y"] = 7, ["x"] = 3, ["name"] = "default:wood", ["z"] = 5, ["meta"] = {["inventory"] = {}, ["fields"] = {}}}, {["y"] = 7, ["x"] = 3, ["name"] = "default:wood", ["z"] = 6, ["meta"] = {["inventory"] = {}, ["fields"] = {}}}, {["y"] = 7, ["x"] = 3, ["name"] = "default:wood", ["z"] = 7, ["meta"] = {["inventory"] = {}, ["fields"] = {}}}, {["y"] = 7, ["x"] = 3, ["name"] = "default:wood", ["z"] = 8, ["meta"] = {["inventory"] = {}, ["fields"] = {}}}, {["y"] = 7, ["x"] = 3, ["name"] = "default:wood", ["z"] = 9, ["meta"] = {["inventory"] = {}, ["fields"] = {}}}, {["y"] = 7, ["x"] = 3, ["name"] = "default:wood", ["z"] = 10, ["meta"] = {["inventory"] = {}, ["fields"] = {}}}, {["y"] = 7, ["x"] = 3, ["name"] = "default:wood", ["z"] = 11, ["meta"] = {["inventory"] = {}, ["fields"] = {}}}, {["y"] = 8, ["x"] = 3, ["name"] = "default:sandstonebrick", ["z"] = 1, ["meta"] = {["inventory"] = {}, ["fields"] = {}}}, {["y"] = 8, ["x"] = 3, ["name"] = "default:sandstonebrick", ["z"] = 2, ["meta"] = {["inventory"] = {}, ["fields"] = {}}}, {["y"] = 8, ["x"] = 3, ["name"] = "default:sandstonebrick", ["z"] = 3, ["meta"] = {["inventory"] = {}, ["fields"] = {}}}, {["y"] = 8, ["x"] = 3, ["name"] = "default:sandstonebrick", ["z"] = 4, ["meta"] = {["inventory"] = {}, ["fields"] = {}}}, {["y"] = 8, ["x"] = 3, ["name"] = "default:sandstonebrick", ["z"] = 5, ["meta"] = {["inventory"] = {}, ["fields"] = {}}}, {["y"] = 8, ["x"] = 3, ["name"] = "default:sandstonebrick", ["z"] = 6, ["meta"] = {["inventory"] = {}, ["fields"] = {}}}, {["y"] = 8, ["x"] = 3, ["name"] = "default:sandstonebrick", ["z"] = 7, ["meta"] = {["inventory"] = {}, ["fields"] = {}}}, {["y"] = 8, ["x"] = 3, ["name"] = "default:sandstonebrick", ["z"] = 8, ["meta"] = {["inventory"] = {}, ["fields"] = {}}}, {["y"] = 8, ["x"] = 3, ["name"] = "default:sandstonebrick", ["z"] = 9, ["meta"] = {["inventory"] = {}, ["fields"] = {}}}, {["y"] = 8, ["x"] = 3, ["name"] = "default:sandstonebrick", ["z"] = 10, ["meta"] = {["inventory"] = {}, ["fields"] = {}}}, {["y"] = 8, ["x"] = 3, ["name"] = "default:sandstonebrick", ["z"] = 11, ["meta"] = {["inventory"] = {}, ["fields"] = {}}}, {["y"] = 9, ["x"] = 3, ["name"] = "moreblocks:panel_sandstonebrick", ["z"] = 1, ["meta"] = {["inventory"] = {}, ["fields"] = {}}, ["param1"] = 111}, {["y"] = 9, ["x"] = 3, ["name"] = "default:sandstonebrick", ["z"] = 2, ["meta"] = {["inventory"] = {}, ["fields"] = {}}}, {["y"] = 9, ["x"] = 3, ["name"] = "default:sandstonebrick", ["z"] = 10, ["meta"] = {["inventory"] = {}, ["fields"] = {}}}, {["y"] = 9, ["x"] = 3, ["name"] = "moreblocks:panel_sandstonebrick", ["z"] = 11, ["meta"] = {["inventory"] = {}, ["fields"] = {}}, ["param2"] = 2, ["param1"] = 79}, {["y"] = 10, ["x"] = 3, ["name"] = "moreblocks:panel_sandstonebrick", ["z"] = 2, ["meta"] = {["inventory"] = {}, ["fields"] = {}}, ["param1"] = 79}, {["y"] = 10, ["x"] = 3, ["name"] = "default:sandstonebrick", ["z"] = 3, ["meta"] = {["inventory"] = {}, ["fields"] = {}}}, {["y"] = 10, ["x"] = 3, ["name"] = "default:sandstonebrick", ["z"] = 9, ["meta"] = {["inventory"] = {}, ["fields"] = {}}}, {["y"] = 10, ["x"] = 3, ["name"] = "moreblocks:panel_sandstonebrick", ["z"] = 10, ["meta"] = {["inventory"] = {}, ["fields"] = {}}, ["param2"] = 2, ["param1"] = 47}, {["y"] = 11, ["x"] = 3, ["name"] = "moreblocks:panel_sandstonebrick", ["z"] = 3, ["meta"] = {["inventory"] = {}, ["fields"] = {}}, ["param1"] = 47}, {["y"] = 11, ["x"] = 3, ["name"] = "default:sandstonebrick", ["z"] = 4, ["meta"] = {["inventory"] = {}, ["fields"] = {}}}, {["y"] = 11, ["x"] = 3, ["name"] = "default:sandstonebrick", ["z"] = 8, ["meta"] = {["inventory"] = {}, ["fields"] = {}}}, {["y"] = 11, ["x"] = 3, ["name"] = "moreblocks:panel_sandstonebrick", ["z"] = 9, ["meta"] = {["inventory"] = {}, ["fields"] = {}}, ["param2"] = 2, ["param1"] = 47}, {["y"] = 12, ["x"] = 3, ["name"] = "moreblocks:panel_sandstonebrick", ["z"] = 4, ["meta"] = {["inventory"] = {}, ["fields"] = {}}, ["param1"] = 47}, {["y"] = 12, ["x"] = 3, ["name"] = "default:sandstonebrick", ["z"] = 5, ["meta"] = {["inventory"] = {}, ["fields"] = {}}}, {["y"] = 12, ["x"] = 3, ["name"] = "default:sandstonebrick", ["z"] = 7, ["meta"] = {["inventory"] = {}, ["fields"] = {}}}, {["y"] = 12, ["x"] = 3, ["name"] = "moreblocks:panel_sandstonebrick", ["z"] = 8, ["meta"] = {["inventory"] = {}, ["fields"] = {}}, ["param2"] = 2, ["param1"] = 47}, {["y"] = 13, ["x"] = 3, ["name"] = "moreblocks:panel_sandstonebrick", ["z"] = 5, ["meta"] = {["inventory"] = {}, ["fields"] = {}}, ["param1"] = 47}, {["y"] = 13, ["x"] = 3, ["name"] = "default:sandstonebrick", ["z"] = 6, ["meta"] = {["inventory"] = {}, ["fields"] = {}}}, {["y"] = 13, ["x"] = 3, ["name"] = "moreblocks:panel_sandstonebrick", ["z"] = 7, ["meta"] = {["inventory"] = {}, ["fields"] = {}}, ["param2"] = 2, ["param1"] = 47}, {["y"] = 0, ["x"] = 4, ["name"] = "default:dirt_with_dry_grass", ["z"] = 0, ["meta"] = {["inventory"] = {}, ["fields"] = {}}}, {["y"] = 0, ["x"] = 4, ["name"] = "default:dirt", ["z"] = 1, ["meta"] = {["inventory"] = {}, ["fields"] = {}}}, {["y"] = 0, ["x"] = 4, ["name"] = "default:stone", ["z"] = 2, ["meta"] = {["inventory"] = {}, ["fields"] = {}}}, {["y"] = 0, ["x"] = 4, ["name"] = "default:stone", ["z"] = 3, ["meta"] = {["inventory"] = {}, ["fields"] = {}}}, {["y"] = 0, ["x"] = 4, ["name"] = "default:stone", ["z"] = 4, ["meta"] = {["inventory"] = {}, ["fields"] = {}}}, {["y"] = 0, ["x"] = 4, ["name"] = "default:stone", ["z"] = 5, ["meta"] = {["inventory"] = {}, ["fields"] = {}}}, {["y"] = 0, ["x"] = 4, ["name"] = "default:stone", ["z"] = 6, ["meta"] = {["inventory"] = {}, ["fields"] = {}}}, {["y"] = 0, ["x"] = 4, ["name"] = "default:stone", ["z"] = 7, ["meta"] = {["inventory"] = {}, ["fields"] = {}}}, {["y"] = 0, ["x"] = 4, ["name"] = "default:stone", ["z"] = 8, ["meta"] = {["inventory"] = {}, ["fields"] = {}}}, {["y"] = 0, ["x"] = 4, ["name"] = "default:stone", ["z"] = 9, ["meta"] = {["inventory"] = {}, ["fields"] = {}}}, {["y"] = 0, ["x"] = 4, ["name"] = "default:stone", ["z"] = 10, ["meta"] = {["inventory"] = {}, ["fields"] = {}}}, {["y"] = 0, ["x"] = 4, ["name"] = "default:stone", ["z"] = 11, ["meta"] = {["inventory"] = {}, ["fields"] = {}}}, {["y"] = 1, ["x"] = 4, ["name"] = "default:acacia_wood", ["z"] = 1, ["meta"] = {["inventory"] = {}, ["fields"] = {}}}, {["y"] = 1, ["x"] = 4, ["name"] = "default:acacia_wood", ["z"] = 11, ["meta"] = {["inventory"] = {}, ["fields"] = {}}}, {["y"] = 2, ["x"] = 4, ["name"] = "default:wood", ["z"] = 1, ["meta"] = {["inventory"] = {}, ["fields"] = {}}}, {["y"] = 2, ["x"] = 4, ["name"] = "default:wood", ["z"] = 11, ["meta"] = {["inventory"] = {}, ["fields"] = {}}}, {["y"] = 3, ["x"] = 4, ["name"] = "default:wood", ["z"] = 1, ["meta"] = {["inventory"] = {}, ["fields"] = {}}}, {["y"] = 3, ["x"] = 4, ["name"] = "default:wood", ["z"] = 11, ["meta"] = {["inventory"] = {}, ["fields"] = {}}}, {["y"] = 4, ["x"] = 4, ["name"] = "default:sandstone", ["z"] = 1, ["meta"] = {["inventory"] = {}, ["fields"] = {}}}, {["y"] = 4, ["x"] = 4, ["name"] = "default:sandstone", ["z"] = 2, ["meta"] = {["inventory"] = {}, ["fields"] = {}}}, {["y"] = 4, ["x"] = 4, ["name"] = "default:sandstone", ["z"] = 3, ["meta"] = {["inventory"] = {}, ["fields"] = {}}}, {["y"] = 4, ["x"] = 4, ["name"] = "default:sandstone", ["z"] = 4, ["meta"] = {["inventory"] = {}, ["fields"] = {}}}, {["y"] = 4, ["x"] = 4, ["name"] = "default:sandstone", ["z"] = 5, ["meta"] = {["inventory"] = {}, ["fields"] = {}}}, {["y"] = 4, ["x"] = 4, ["name"] = "default:sandstone", ["z"] = 6, ["meta"] = {["inventory"] = {}, ["fields"] = {}}}, {["y"] = 4, ["x"] = 4, ["name"] = "default:sandstone", ["z"] = 7, ["meta"] = {["inventory"] = {}, ["fields"] = {}}}, {["y"] = 4, ["x"] = 4, ["name"] = "default:sandstone", ["z"] = 8, ["meta"] = {["inventory"] = {}, ["fields"] = {}}}, {["y"] = 4, ["x"] = 4, ["name"] = "default:sandstone", ["z"] = 9, ["meta"] = {["inventory"] = {}, ["fields"] = {}}}, {["y"] = 4, ["x"] = 4, ["name"] = "default:sandstone", ["z"] = 10, ["meta"] = {["inventory"] = {}, ["fields"] = {}}}, {["y"] = 4, ["x"] = 4, ["name"] = "default:sandstone", ["z"] = 11, ["meta"] = {["inventory"] = {}, ["fields"] = {}}}, {["y"] = 5, ["x"] = 4, ["name"] = "default:acacia_wood", ["z"] = 1, ["meta"] = {["inventory"] = {}, ["fields"] = {}}}, {["y"] = 5, ["x"] = 4, ["name"] = "default:acacia_wood", ["z"] = 5, ["meta"] = {["inventory"] = {}, ["fields"] = {}}}, {["y"] = 5, ["x"] = 4, ["name"] = "default:acacia_wood", ["z"] = 11, ["meta"] = {["inventory"] = {}, ["fields"] = {}}}, {["y"] = 6, ["x"] = 4, ["name"] = "default:wood", ["z"] = 1, ["meta"] = {["inventory"] = {}, ["fields"] = {}}}, {["y"] = 6, ["x"] = 4, ["name"] = "default:acacia_wood", ["z"] = 5, ["meta"] = {["inventory"] = {}, ["fields"] = {}}}, {["y"] = 6, ["x"] = 4, ["name"] = "default:acacia_wood", ["z"] = 11, ["meta"] = {["inventory"] = {}, ["fields"] = {}}}, {["y"] = 7, ["x"] = 4, ["name"] = "default:wood", ["z"] = 1, ["meta"] = {["inventory"] = {}, ["fields"] = {}}}, {["y"] = 7, ["x"] = 4, ["name"] = "default:wood", ["z"] = 5, ["meta"] = {["inventory"] = {}, ["fields"] = {}}}, {["y"] = 7, ["x"] = 4, ["name"] = "default:wood", ["z"] = 11, ["meta"] = {["inventory"] = {}, ["fields"] = {}}}, {["y"] = 8, ["x"] = 4, ["name"] = "default:sandstonebrick", ["z"] = 1, ["meta"] = {["inventory"] = {}, ["fields"] = {}}}, {["y"] = 8, ["x"] = 4, ["name"] = "default:sandstonebrick", ["z"] = 2, ["meta"] = {["inventory"] = {}, ["fields"] = {}}}, {["y"] = 8, ["x"] = 4, ["name"] = "default:sandstonebrick", ["z"] = 3, ["meta"] = {["inventory"] = {}, ["fields"] = {}}}, {["y"] = 8, ["x"] = 4, ["name"] = "default:sandstonebrick", ["z"] = 4, ["meta"] = {["inventory"] = {}, ["fields"] = {}}}, {["y"] = 8, ["x"] = 4, ["name"] = "default:sandstonebrick", ["z"] = 5, ["meta"] = {["inventory"] = {}, ["fields"] = {}}}, {["y"] = 8, ["x"] = 4, ["name"] = "default:sandstonebrick", ["z"] = 6, ["meta"] = {["inventory"] = {}, ["fields"] = {}}}, {["y"] = 8, ["x"] = 4, ["name"] = "default:sandstonebrick", ["z"] = 7, ["meta"] = {["inventory"] = {}, ["fields"] = {}}}, {["y"] = 8, ["x"] = 4, ["name"] = "default:sandstonebrick", ["z"] = 8, ["meta"] = {["inventory"] = {}, ["fields"] = {}}}, {["y"] = 8, ["x"] = 4, ["name"] = "default:sandstonebrick", ["z"] = 9, ["meta"] = {["inventory"] = {}, ["fields"] = {}}}, {["y"] = 8, ["x"] = 4, ["name"] = "default:sandstonebrick", ["z"] = 10, ["meta"] = {["inventory"] = {}, ["fields"] = {}}}, {["y"] = 8, ["x"] = 4, ["name"] = "default:sandstonebrick", ["z"] = 11, ["meta"] = {["inventory"] = {}, ["fields"] = {}}}, {["y"] = 9, ["x"] = 4, ["name"] = "moreblocks:panel_sandstonebrick", ["z"] = 1, ["meta"] = {["inventory"] = {}, ["fields"] = {}}, ["param1"] = 95}, {["y"] = 9, ["x"] = 4, ["name"] = "default:sandstonebrick", ["z"] = 2, ["meta"] = {["inventory"] = {}, ["fields"] = {}}}, {["y"] = 9, ["x"] = 4, ["name"] = "default:sandstonebrick", ["z"] = 10, ["meta"] = {["inventory"] = {}, ["fields"] = {}}}, {["y"] = 9, ["x"] = 4, ["name"] = "moreblocks:panel_sandstonebrick", ["z"] = 11, ["meta"] = {["inventory"] = {}, ["fields"] = {}}, ["param2"] = 2, ["param1"] = 79}, {["y"] = 10, ["x"] = 4, ["name"] = "moreblocks:panel_sandstonebrick", ["z"] = 2, ["meta"] = {["inventory"] = {}, ["fields"] = {}}, ["param1"] = 63}, {["y"] = 10, ["x"] = 4, ["name"] = "default:sandstonebrick", ["z"] = 3, ["meta"] = {["inventory"] = {}, ["fields"] = {}}}, {["y"] = 10, ["x"] = 4, ["name"] = "default:sandstonebrick", ["z"] = 9, ["meta"] = {["inventory"] = {}, ["fields"] = {}}}, {["y"] = 10, ["x"] = 4, ["name"] = "moreblocks:panel_sandstonebrick", ["z"] = 10, ["meta"] = {["inventory"] = {}, ["fields"] = {}}, ["param2"] = 2, ["param1"] = 47}, {["y"] = 11, ["x"] = 4, ["name"] = "moreblocks:panel_sandstonebrick", ["z"] = 3, ["meta"] = {["inventory"] = {}, ["fields"] = {}}, ["param1"] = 31}, {["y"] = 11, ["x"] = 4, ["name"] = "default:sandstonebrick", ["z"] = 4, ["meta"] = {["inventory"] = {}, ["fields"] = {}}}, {["y"] = 11, ["x"] = 4, ["name"] = "default:sandstonebrick", ["z"] = 8, ["meta"] = {["inventory"] = {}, ["fields"] = {}}}, {["y"] = 11, ["x"] = 4, ["name"] = "moreblocks:panel_sandstonebrick", ["z"] = 9, ["meta"] = {["inventory"] = {}, ["fields"] = {}}, ["param2"] = 2, ["param1"] = 31}, {["y"] = 12, ["x"] = 4, ["name"] = "moreblocks:panel_sandstonebrick", ["z"] = 4, ["meta"] = {["inventory"] = {}, ["fields"] = {}}, ["param1"] = 31}, {["y"] = 12, ["x"] = 4, ["name"] = "default:sandstonebrick", ["z"] = 5, ["meta"] = {["inventory"] = {}, ["fields"] = {}}}, {["y"] = 12, ["x"] = 4, ["name"] = "default:sandstonebrick", ["z"] = 7, ["meta"] = {["inventory"] = {}, ["fields"] = {}}}, {["y"] = 12, ["x"] = 4, ["name"] = "moreblocks:panel_sandstonebrick", ["z"] = 8, ["meta"] = {["inventory"] = {}, ["fields"] = {}}, ["param2"] = 2, ["param1"] = 31}, {["y"] = 13, ["x"] = 4, ["name"] = "moreblocks:panel_sandstonebrick", ["z"] = 5, ["meta"] = {["inventory"] = {}, ["fields"] = {}}, ["param1"] = 31}, {["y"] = 13, ["x"] = 4, ["name"] = "default:sandstonebrick", ["z"] = 6, ["meta"] = {["inventory"] = {}, ["fields"] = {}}}, {["y"] = 13, ["x"] = 4, ["name"] = "moreblocks:panel_sandstonebrick", ["z"] = 7, ["meta"] = {["inventory"] = {}, ["fields"] = {}}, ["param2"] = 2, ["param1"] = 31}, {["y"] = 0, ["x"] = 5, ["name"] = "default:dirt_with_grass", ["z"] = 0, ["meta"] = {["inventory"] = {}, ["fields"] = {}}}, {["y"] = 0, ["x"] = 5, ["name"] = "default:cobble", ["z"] = 1, ["meta"] = {["inventory"] = {}, ["fields"] = {}}}, {["y"] = 0, ["x"] = 5, ["name"] = "default:stone", ["z"] = 2, ["meta"] = {["inventory"] = {}, ["fields"] = {}}}, {["y"] = 0, ["x"] = 5, ["name"] = "default:stone", ["z"] = 3, ["meta"] = {["inventory"] = {}, ["fields"] = {}}}, {["y"] = 0, ["x"] = 5, ["name"] = "default:stone", ["z"] = 4, ["meta"] = {["inventory"] = {}, ["fields"] = {}}}, {["y"] = 0, ["x"] = 5, ["name"] = "default:stone", ["z"] = 5, ["meta"] = {["inventory"] = {}, ["fields"] = {}}}, {["y"] = 0, ["x"] = 5, ["name"] = "default:stone", ["z"] = 6, ["meta"] = {["inventory"] = {}, ["fields"] = {}}}, {["y"] = 0, ["x"] = 5, ["name"] = "default:stone", ["z"] = 7, ["meta"] = {["inventory"] = {}, ["fields"] = {}}}, {["y"] = 0, ["x"] = 5, ["name"] = "default:stone", ["z"] = 8, ["meta"] = {["inventory"] = {}, ["fields"] = {}}}, {["y"] = 0, ["x"] = 5, ["name"] = "default:stone", ["z"] = 9, ["meta"] = {["inventory"] = {}, ["fields"] = {}}}, {["y"] = 0, ["x"] = 5, ["name"] = "default:stone", ["z"] = 10, ["meta"] = {["inventory"] = {}, ["fields"] = {}}}, {["y"] = 0, ["x"] = 5, ["name"] = "default:stone", ["z"] = 11, ["meta"] = {["inventory"] = {}, ["fields"] = {}}}, {["y"] = 1, ["x"] = 5, ["name"] = "doors:door_wood_a", ["z"] = 1, ["meta"] = {["inventory"] = {}, ["fields"] = {["state"] = "0"}}, ["param1"] = 125}, {["y"] = 1, ["x"] = 5, ["name"] = "doors:door_wood_a", ["z"] = 11, ["meta"] = {["inventory"] = {}, ["fields"] = {["state"] = "0"}}, ["param2"] = 2, ["param1"] = 173}, {["y"] = 2, ["x"] = 5, ["name"] = "doors:hidden", ["z"] = 1, ["meta"] = {["inventory"] = {}, ["fields"] = {}}, ["param1"] = 141}, {["y"] = 2, ["x"] = 5, ["name"] = "doors:hidden", ["z"] = 11, ["meta"] = {["inventory"] = {}, ["fields"] = {}}, ["param2"] = 2, ["param1"] = 189}, {["y"] = 3, ["x"] = 5, ["name"] = "default:wood", ["z"] = 1, ["meta"] = {["inventory"] = {}, ["fields"] = {}}}, {["y"] = 3, ["x"] = 5, ["name"] = "homedecor:glowlight_quarter_white", ["z"] = 6, ["meta"] = {["inventory"] = {}, ["fields"] = {}}, ["param2"] = 20}, {["y"] = 3, ["x"] = 5, ["name"] = "homedecor:glowlight_small_cube_white", ["z"] = 10, ["meta"] = {["inventory"] = {}, ["fields"] = {}}, ["param2"] = 9}, {["y"] = 3, ["x"] = 5, ["name"] = "default:wood", ["z"] = 11, ["meta"] = {["inventory"] = {}, ["fields"] = {}}}, {["y"] = 4, ["x"] = 5, ["name"] = "default:sandstone", ["z"] = 1, ["meta"] = {["inventory"] = {}, ["fields"] = {}}}, {["y"] = 4, ["x"] = 5, ["name"] = "default:sandstone", ["z"] = 2, ["meta"] = {["inventory"] = {}, ["fields"] = {}}}, {["y"] = 4, ["x"] = 5, ["name"] = "default:sandstone", ["z"] = 3, ["meta"] = {["inventory"] = {}, ["fields"] = {}}}, {["y"] = 4, ["x"] = 5, ["name"] = "default:sandstone", ["z"] = 4, ["meta"] = {["inventory"] = {}, ["fields"] = {}}}, {["y"] = 4, ["x"] = 5, ["name"] = "default:sandstone", ["z"] = 5, ["meta"] = {["inventory"] = {}, ["fields"] = {}}}, {["y"] = 4, ["x"] = 5, ["name"] = "default:sandstone", ["z"] = 6, ["meta"] = {["inventory"] = {}, ["fields"] = {}}}, {["y"] = 4, ["x"] = 5, ["name"] = "default:sandstone", ["z"] = 7, ["meta"] = {["inventory"] = {}, ["fields"] = {}}}, {["y"] = 4, ["x"] = 5, ["name"] = "default:sandstone", ["z"] = 8, ["meta"] = {["inventory"] = {}, ["fields"] = {}}}, {["y"] = 4, ["x"] = 5, ["name"] = "default:sandstone", ["z"] = 9, ["meta"] = {["inventory"] = {}, ["fields"] = {}}}, {["y"] = 4, ["x"] = 5, ["name"] = "default:sandstone", ["z"] = 10, ["meta"] = {["inventory"] = {}, ["fields"] = {}}}, {["y"] = 4, ["x"] = 5, ["name"] = "default:sandstone", ["z"] = 11, ["meta"] = {["inventory"] = {}, ["fields"] = {}}}, {["y"] = 5, ["x"] = 5, ["name"] = "default:acacia_wood", ["z"] = 1, ["meta"] = {["inventory"] = {}, ["fields"] = {}}}, {["y"] = 5, ["x"] = 5, ["name"] = "default:acacia_wood", ["z"] = 5, ["meta"] = {["inventory"] = {}, ["fields"] = {}}}, {["y"] = 5, ["x"] = 5, ["name"] = "default:acacia_wood", ["z"] = 11, ["meta"] = {["inventory"] = {}, ["fields"] = {}}}, {["y"] = 6, ["x"] = 5, ["name"] = "default:wood", ["z"] = 1, ["meta"] = {["inventory"] = {}, ["fields"] = {}}}, {["y"] = 6, ["x"] = 5, ["name"] = "default:wood", ["z"] = 5, ["meta"] = {["inventory"] = {}, ["fields"] = {}}}, {["y"] = 6, ["x"] = 5, ["name"] = "xpanes:pane_5", ["z"] = 11, ["meta"] = {["inventory"] = {}, ["fields"] = {}}, ["param1"] = 141}, {["y"] = 7, ["x"] = 5, ["name"] = "default:wood", ["z"] = 1, ["meta"] = {["inventory"] = {}, ["fields"] = {}}}, {["y"] = 7, ["x"] = 5, ["name"] = "default:wood", ["z"] = 5, ["meta"] = {["inventory"] = {}, ["fields"] = {}}}, {["y"] = 7, ["x"] = 5, ["name"] = "xpanes:pane_5", ["z"] = 11, ["meta"] = {["inventory"] = {}, ["fields"] = {}}, ["param1"] = 157}, {["y"] = 8, ["x"] = 5, ["name"] = "default:sandstonebrick", ["z"] = 1, ["meta"] = {["inventory"] = {}, ["fields"] = {}}}, {["y"] = 8, ["x"] = 5, ["name"] = "default:sandstonebrick", ["z"] = 2, ["meta"] = {["inventory"] = {}, ["fields"] = {}}}, {["y"] = 8, ["x"] = 5, ["name"] = "default:sandstonebrick", ["z"] = 3, ["meta"] = {["inventory"] = {}, ["fields"] = {}}}, {["y"] = 8, ["x"] = 5, ["name"] = "default:sandstonebrick", ["z"] = 4, ["meta"] = {["inventory"] = {}, ["fields"] = {}}}, {["y"] = 8, ["x"] = 5, ["name"] = "default:sandstonebrick", ["z"] = 5, ["meta"] = {["inventory"] = {}, ["fields"] = {}}}, {["y"] = 8, ["x"] = 5, ["name"] = "default:sandstonebrick", ["z"] = 6, ["meta"] = {["inventory"] = {}, ["fields"] = {}}}, {["y"] = 8, ["x"] = 5, ["name"] = "default:sandstonebrick", ["z"] = 7, ["meta"] = {["inventory"] = {}, ["fields"] = {}}}, {["y"] = 8, ["x"] = 5, ["name"] = "default:sandstonebrick", ["z"] = 8, ["meta"] = {["inventory"] = {}, ["fields"] = {}}}, {["y"] = 8, ["x"] = 5, ["name"] = "default:sandstonebrick", ["z"] = 9, ["meta"] = {["inventory"] = {}, ["fields"] = {}}}, {["y"] = 8, ["x"] = 5, ["name"] = "default:sandstonebrick", ["z"] = 10, ["meta"] = {["inventory"] = {}, ["fields"] = {}}}, {["y"] = 8, ["x"] = 5, ["name"] = "default:sandstonebrick", ["z"] = 11, ["meta"] = {["inventory"] = {}, ["fields"] = {}}}, {["y"] = 9, ["x"] = 5, ["name"] = "moreblocks:panel_sandstonebrick", ["z"] = 1, ["meta"] = {["inventory"] = {}, ["fields"] = {}}, ["param1"] = 95}, {["y"] = 9, ["x"] = 5, ["name"] = "default:sandstonebrick", ["z"] = 2, ["meta"] = {["inventory"] = {}, ["fields"] = {}}}, {["y"] = 9, ["x"] = 5, ["name"] = "default:sandstonebrick", ["z"] = 10, ["meta"] = {["inventory"] = {}, ["fields"] = {}}}, {["y"] = 9, ["x"] = 5, ["name"] = "moreblocks:panel_sandstonebrick", ["z"] = 11, ["meta"] = {["inventory"] = {}, ["fields"] = {}}, ["param2"] = 2, ["param1"] = 95}, {["y"] = 10, ["x"] = 5, ["name"] = "moreblocks:panel_sandstonebrick", ["z"] = 2, ["meta"] = {["inventory"] = {}, ["fields"] = {}}, ["param1"] = 63}, {["y"] = 10, ["x"] = 5, ["name"] = "default:sandstonebrick", ["z"] = 3, ["meta"] = {["inventory"] = {}, ["fields"] = {}}}, {["y"] = 10, ["x"] = 5, ["name"] = "default:sandstonebrick", ["z"] = 9, ["meta"] = {["inventory"] = {}, ["fields"] = {}}}, {["y"] = 10, ["x"] = 5, ["name"] = "moreblocks:panel_sandstonebrick", ["z"] = 10, ["meta"] = {["inventory"] = {}, ["fields"] = {}}, ["param2"] = 2, ["param1"] = 63}, {["y"] = 11, ["x"] = 5, ["name"] = "moreblocks:panel_sandstonebrick", ["z"] = 3, ["meta"] = {["inventory"] = {}, ["fields"] = {}}, ["param1"] = 31}, {["y"] = 11, ["x"] = 5, ["name"] = "default:sandstonebrick", ["z"] = 4, ["meta"] = {["inventory"] = {}, ["fields"] = {}}}, {["y"] = 11, ["x"] = 5, ["name"] = "default:sandstonebrick", ["z"] = 8, ["meta"] = {["inventory"] = {}, ["fields"] = {}}}, {["y"] = 11, ["x"] = 5, ["name"] = "moreblocks:panel_sandstonebrick", ["z"] = 9, ["meta"] = {["inventory"] = {}, ["fields"] = {}}, ["param2"] = 2, ["param1"] = 31}, {["y"] = 12, ["x"] = 5, ["name"] = "moreblocks:panel_sandstonebrick", ["z"] = 4, ["meta"] = {["inventory"] = {}, ["fields"] = {}}, ["param1"] = 15}, {["y"] = 12, ["x"] = 5, ["name"] = "default:sandstonebrick", ["z"] = 5, ["meta"] = {["inventory"] = {}, ["fields"] = {}}}, {["y"] = 12, ["x"] = 5, ["name"] = "default:sandstonebrick", ["z"] = 7, ["meta"] = {["inventory"] = {}, ["fields"] = {}}}, {["y"] = 12, ["x"] = 5, ["name"] = "moreblocks:panel_sandstonebrick", ["z"] = 8, ["meta"] = {["inventory"] = {}, ["fields"] = {}}, ["param2"] = 2, ["param1"] = 15}, {["y"] = 13, ["x"] = 5, ["name"] = "moreblocks:panel_sandstonebrick", ["z"] = 5, ["meta"] = {["inventory"] = {}, ["fields"] = {}}, ["param1"] = 15}, {["y"] = 13, ["x"] = 5, ["name"] = "default:sandstonebrick", ["z"] = 6, ["meta"] = {["inventory"] = {}, ["fields"] = {}}}, {["y"] = 13, ["x"] = 5, ["name"] = "moreblocks:panel_sandstonebrick", ["z"] = 7, ["meta"] = {["inventory"] = {}, ["fields"] = {}}, ["param2"] = 2, ["param1"] = 15}, {["y"] = 0, ["x"] = 6, ["name"] = "default:dirt_with_grass", ["z"] = 0, ["meta"] = {["inventory"] = {}, ["fields"] = {}}}, {["y"] = 0, ["x"] = 6, ["name"] = "default:dirt", ["z"] = 1, ["meta"] = {["inventory"] = {}, ["fields"] = {}}}, {["y"] = 0, ["x"] = 6, ["name"] = "default:stone", ["z"] = 2, ["meta"] = {["inventory"] = {}, ["fields"] = {}}}, {["y"] = 0, ["x"] = 6, ["name"] = "default:stone", ["z"] = 3, ["meta"] = {["inventory"] = {}, ["fields"] = {}}}, {["y"] = 0, ["x"] = 6, ["name"] = "default:stone", ["z"] = 4, ["meta"] = {["inventory"] = {}, ["fields"] = {}}}, {["y"] = 0, ["x"] = 6, ["name"] = "default:stone", ["z"] = 5, ["meta"] = {["inventory"] = {}, ["fields"] = {}}}, {["y"] = 0, ["x"] = 6, ["name"] = "default:stone", ["z"] = 6, ["meta"] = {["inventory"] = {}, ["fields"] = {}}}, {["y"] = 0, ["x"] = 6, ["name"] = "default:stone", ["z"] = 7, ["meta"] = {["inventory"] = {}, ["fields"] = {}}}, {["y"] = 0, ["x"] = 6, ["name"] = "default:stone", ["z"] = 8, ["meta"] = {["inventory"] = {}, ["fields"] = {}}}, {["y"] = 0, ["x"] = 6, ["name"] = "default:stone", ["z"] = 9, ["meta"] = {["inventory"] = {}, ["fields"] = {}}}, {["y"] = 0, ["x"] = 6, ["name"] = "default:stone", ["z"] = 10, ["meta"] = {["inventory"] = {}, ["fields"] = {}}}, {["y"] = 0, ["x"] = 6, ["name"] = "default:stone", ["z"] = 11, ["meta"] = {["inventory"] = {}, ["fields"] = {}}}, {["y"] = 1, ["x"] = 6, ["name"] = "default:acacia_wood", ["z"] = 1, ["meta"] = {["inventory"] = {}, ["fields"] = {}}}, {["y"] = 1, ["x"] = 6, ["name"] = "default:acacia_wood", ["z"] = 11, ["meta"] = {["inventory"] = {}, ["fields"] = {}}}, {["y"] = 2, ["x"] = 6, ["name"] = "default:wood", ["z"] = 1, ["meta"] = {["inventory"] = {}, ["fields"] = {}}}, {["y"] = 2, ["x"] = 6, ["name"] = "default:wood", ["z"] = 11, ["meta"] = {["inventory"] = {}, ["fields"] = {}}}, {["y"] = 3, ["x"] = 6, ["name"] = "default:wood", ["z"] = 1, ["meta"] = {["inventory"] = {}, ["fields"] = {}}}, {["y"] = 3, ["x"] = 6, ["name"] = "default:wood", ["z"] = 11, ["meta"] = {["inventory"] = {}, ["fields"] = {}}}, {["y"] = 4, ["x"] = 6, ["name"] = "default:sandstone", ["z"] = 1, ["meta"] = {["inventory"] = {}, ["fields"] = {}}}, {["y"] = 4, ["x"] = 6, ["name"] = "default:sandstone", ["z"] = 2, ["meta"] = {["inventory"] = {}, ["fields"] = {}}}, {["y"] = 4, ["x"] = 6, ["name"] = "default:sandstone", ["z"] = 3, ["meta"] = {["inventory"] = {}, ["fields"] = {}}}, {["y"] = 4, ["x"] = 6, ["name"] = "default:sandstone", ["z"] = 4, ["meta"] = {["inventory"] = {}, ["fields"] = {}}}, {["y"] = 4, ["x"] = 6, ["name"] = "default:sandstone", ["z"] = 5, ["meta"] = {["inventory"] = {}, ["fields"] = {}}}, {["y"] = 4, ["x"] = 6, ["name"] = "default:sandstone", ["z"] = 6, ["meta"] = {["inventory"] = {}, ["fields"] = {}}}, {["y"] = 4, ["x"] = 6, ["name"] = "default:sandstone", ["z"] = 7, ["meta"] = {["inventory"] = {}, ["fields"] = {}}}, {["y"] = 4, ["x"] = 6, ["name"] = "default:sandstone", ["z"] = 8, ["meta"] = {["inventory"] = {}, ["fields"] = {}}}, {["y"] = 4, ["x"] = 6, ["name"] = "default:sandstone", ["z"] = 9, ["meta"] = {["inventory"] = {}, ["fields"] = {}}}, {["y"] = 4, ["x"] = 6, ["name"] = "default:sandstone", ["z"] = 10, ["meta"] = {["inventory"] = {}, ["fields"] = {}}}, {["y"] = 4, ["x"] = 6, ["name"] = "default:sandstone", ["z"] = 11, ["meta"] = {["inventory"] = {}, ["fields"] = {}}}, {["y"] = 5, ["x"] = 6, ["name"] = "default:acacia_wood", ["z"] = 1, ["meta"] = {["inventory"] = {}, ["fields"] = {}}}, {["y"] = 5, ["x"] = 6, ["name"] = "homedecor:door_wood_plain_left", ["z"] = 5, ["meta"] = {["inventory"] = {}, ["fields"] = {["closed"] = "1"}}, ["param2"] = 2, ["param1"] = 136}, {["y"] = 5, ["x"] = 6, ["name"] = "default:acacia_wood", ["z"] = 11, ["meta"] = {["inventory"] = {}, ["fields"] = {}}}, {["y"] = 6, ["x"] = 6, ["name"] = "xpanes:pane_5", ["z"] = 1, ["meta"] = {["inventory"] = {}, ["fields"] = {}}, ["param1"] = 157}, {["y"] = 6, ["x"] = 6, ["name"] = "xpanes:pane_5", ["z"] = 11, ["meta"] = {["inventory"] = {}, ["fields"] = {}}, ["param1"] = 157}, {["y"] = 7, ["x"] = 6, ["name"] = "xpanes:pane_5", ["z"] = 1, ["meta"] = {["inventory"] = {}, ["fields"] = {}}, ["param1"] = 173}, {["y"] = 7, ["x"] = 6, ["name"] = "default:wood", ["z"] = 5, ["meta"] = {["inventory"] = {}, ["fields"] = {}}}, {["y"] = 7, ["x"] = 6, ["name"] = "homedecor:glowlight_quarter_white", ["z"] = 8, ["meta"] = {["inventory"] = {}, ["fields"] = {}}, ["param2"] = 22}, {["y"] = 7, ["x"] = 6, ["name"] = "xpanes:pane_5", ["z"] = 11, ["meta"] = {["inventory"] = {}, ["fields"] = {}}, ["param1"] = 173}, {["y"] = 8, ["x"] = 6, ["name"] = "default:sandstonebrick", ["z"] = 1, ["meta"] = {["inventory"] = {}, ["fields"] = {}}}, {["y"] = 8, ["x"] = 6, ["name"] = "default:sandstonebrick", ["z"] = 2, ["meta"] = {["inventory"] = {}, ["fields"] = {}}}, {["y"] = 8, ["x"] = 6, ["name"] = "default:sandstonebrick", ["z"] = 3, ["meta"] = {["inventory"] = {}, ["fields"] = {}}}, {["y"] = 8, ["x"] = 6, ["name"] = "default:sandstonebrick", ["z"] = 4, ["meta"] = {["inventory"] = {}, ["fields"] = {}}}, {["y"] = 8, ["x"] = 6, ["name"] = "default:sandstonebrick", ["z"] = 5, ["meta"] = {["inventory"] = {}, ["fields"] = {}}}, {["y"] = 8, ["x"] = 6, ["name"] = "default:sandstonebrick", ["z"] = 6, ["meta"] = {["inventory"] = {}, ["fields"] = {}}}, {["y"] = 8, ["x"] = 6, ["name"] = "default:sandstonebrick", ["z"] = 7, ["meta"] = {["inventory"] = {}, ["fields"] = {}}}, {["y"] = 8, ["x"] = 6, ["name"] = "default:sandstonebrick", ["z"] = 8, ["meta"] = {["inventory"] = {}, ["fields"] = {}}}, {["y"] = 8, ["x"] = 6, ["name"] = "default:sandstonebrick", ["z"] = 9, ["meta"] = {["inventory"] = {}, ["fields"] = {}}}, {["y"] = 8, ["x"] = 6, ["name"] = "default:sandstonebrick", ["z"] = 10, ["meta"] = {["inventory"] = {}, ["fields"] = {}}}, {["y"] = 8, ["x"] = 6, ["name"] = "default:sandstonebrick", ["z"] = 11, ["meta"] = {["inventory"] = {}, ["fields"] = {}}}, {["y"] = 9, ["x"] = 6, ["name"] = "moreblocks:panel_sandstonebrick", ["z"] = 1, ["meta"] = {["inventory"] = {}, ["fields"] = {}}, ["param1"] = 111}, {["y"] = 9, ["x"] = 6, ["name"] = "default:sandstonebrick", ["z"] = 2, ["meta"] = {["inventory"] = {}, ["fields"] = {}}}, {["y"] = 9, ["x"] = 6, ["name"] = "default:sandstonebrick", ["z"] = 10, ["meta"] = {["inventory"] = {}, ["fields"] = {}}}, {["y"] = 9, ["x"] = 6, ["name"] = "moreblocks:panel_sandstonebrick", ["z"] = 11, ["meta"] = {["inventory"] = {}, ["fields"] = {}}, ["param2"] = 2, ["param1"] = 111}, {["y"] = 10, ["x"] = 6, ["name"] = "moreblocks:panel_sandstonebrick", ["z"] = 2, ["meta"] = {["inventory"] = {}, ["fields"] = {}}, ["param1"] = 79}, {["y"] = 10, ["x"] = 6, ["name"] = "default:sandstonebrick", ["z"] = 3, ["meta"] = {["inventory"] = {}, ["fields"] = {}}}, {["y"] = 10, ["x"] = 6, ["name"] = "default:sandstonebrick", ["z"] = 9, ["meta"] = {["inventory"] = {}, ["fields"] = {}}}, {["y"] = 10, ["x"] = 6, ["name"] = "moreblocks:panel_sandstonebrick", ["z"] = 10, ["meta"] = {["inventory"] = {}, ["fields"] = {}}, ["param2"] = 2, ["param1"] = 79}, {["y"] = 11, ["x"] = 6, ["name"] = "moreblocks:panel_sandstonebrick", ["z"] = 3, ["meta"] = {["inventory"] = {}, ["fields"] = {}}, ["param1"] = 47}, {["y"] = 11, ["x"] = 6, ["name"] = "default:sandstonebrick", ["z"] = 4, ["meta"] = {["inventory"] = {}, ["fields"] = {}}}, {["y"] = 11, ["x"] = 6, ["name"] = "default:sandstonebrick", ["z"] = 8, ["meta"] = {["inventory"] = {}, ["fields"] = {}}}, {["y"] = 11, ["x"] = 6, ["name"] = "moreblocks:panel_sandstonebrick", ["z"] = 9, ["meta"] = {["inventory"] = {}, ["fields"] = {}}, ["param2"] = 2, ["param1"] = 47}, {["y"] = 12, ["x"] = 6, ["name"] = "moreblocks:panel_sandstonebrick", ["z"] = 4, ["meta"] = {["inventory"] = {}, ["fields"] = {}}, ["param1"] = 15}, {["y"] = 12, ["x"] = 6, ["name"] = "default:sandstonebrick", ["z"] = 5, ["meta"] = {["inventory"] = {}, ["fields"] = {}}}, {["y"] = 12, ["x"] = 6, ["name"] = "default:sandstonebrick", ["z"] = 7, ["meta"] = {["inventory"] = {}, ["fields"] = {}}}, {["y"] = 12, ["x"] = 6, ["name"] = "moreblocks:panel_sandstonebrick", ["z"] = 8, ["meta"] = {["inventory"] = {}, ["fields"] = {}}, ["param2"] = 2, ["param1"] = 15}, {["y"] = 13, ["x"] = 6, ["name"] = "moreblocks:panel_sandstonebrick", ["z"] = 5, ["meta"] = {["inventory"] = {}, ["fields"] = {}}, ["param1"] = 15}, {["y"] = 13, ["x"] = 6, ["name"] = "default:sandstonebrick", ["z"] = 6, ["meta"] = {["inventory"] = {}, ["fields"] = {}}}, {["y"] = 13, ["x"] = 6, ["name"] = "moreblocks:panel_sandstonebrick", ["z"] = 7, ["meta"] = {["inventory"] = {}, ["fields"] = {}}, ["param2"] = 2, ["param1"] = 15}, {["y"] = 0, ["x"] = 7, ["name"] = "default:dirt_with_grass", ["z"] = 0, ["meta"] = {["inventory"] = {}, ["fields"] = {}}}, {["y"] = 0, ["x"] = 7, ["name"] = "default:dirt", ["z"] = 1, ["meta"] = {["inventory"] = {}, ["fields"] = {}}}, {["y"] = 0, ["x"] = 7, ["name"] = "default:stone", ["z"] = 2, ["meta"] = {["inventory"] = {}, ["fields"] = {}}}, {["y"] = 0, ["x"] = 7, ["name"] = "default:stone", ["z"] = 3, ["meta"] = {["inventory"] = {}, ["fields"] = {}}}, {["y"] = 0, ["x"] = 7, ["name"] = "default:stone", ["z"] = 4, ["meta"] = {["inventory"] = {}, ["fields"] = {}}}, {["y"] = 0, ["x"] = 7, ["name"] = "default:stone", ["z"] = 5, ["meta"] = {["inventory"] = {}, ["fields"] = {}}}, {["y"] = 0, ["x"] = 7, ["name"] = "default:stone", ["z"] = 6, ["meta"] = {["inventory"] = {}, ["fields"] = {}}}, {["y"] = 0, ["x"] = 7, ["name"] = "default:stone", ["z"] = 7, ["meta"] = {["inventory"] = {}, ["fields"] = {}}}, {["y"] = 0, ["x"] = 7, ["name"] = "default:stone", ["z"] = 8, ["meta"] = {["inventory"] = {}, ["fields"] = {}}}, {["y"] = 0, ["x"] = 7, ["name"] = "default:stone", ["z"] = 9, ["meta"] = {["inventory"] = {}, ["fields"] = {}}}, {["y"] = 0, ["x"] = 7, ["name"] = "default:stone", ["z"] = 10, ["meta"] = {["inventory"] = {}, ["fields"] = {}}}, {["y"] = 0, ["x"] = 7, ["name"] = "default:dirt", ["z"] = 11, ["meta"] = {["inventory"] = {}, ["fields"] = {}}}, {["y"] = 1, ["x"] = 7, ["name"] = "default:acacia_wood", ["z"] = 1, ["meta"] = {["inventory"] = {}, ["fields"] = {}}}, {["y"] = 1, ["x"] = 7, ["name"] = "default:acacia_wood", ["z"] = 11, ["meta"] = {["inventory"] = {}, ["fields"] = {}}}, {["y"] = 2, ["x"] = 7, ["name"] = "xpanes:pane_5", ["z"] = 1, ["meta"] = {["inventory"] = {}, ["fields"] = {}}, ["param1"] = 173}, {["y"] = 2, ["x"] = 7, ["name"] = "xpanes:pane_5", ["z"] = 11, ["meta"] = {["inventory"] = {}, ["fields"] = {}}, ["param1"] = 173}, {["y"] = 3, ["x"] = 7, ["name"] = "default:wood", ["z"] = 1, ["meta"] = {["inventory"] = {}, ["fields"] = {}}}, {["y"] = 3, ["x"] = 7, ["name"] = "default:wood", ["z"] = 11, ["meta"] = {["inventory"] = {}, ["fields"] = {}}}, {["y"] = 4, ["x"] = 7, ["name"] = "default:sandstone", ["z"] = 1, ["meta"] = {["inventory"] = {}, ["fields"] = {}}}, {["y"] = 4, ["x"] = 7, ["name"] = "default:sandstone", ["z"] = 2, ["meta"] = {["inventory"] = {}, ["fields"] = {}}}, {["y"] = 4, ["x"] = 7, ["name"] = "default:sandstone", ["z"] = 3, ["meta"] = {["inventory"] = {}, ["fields"] = {}}}, {["y"] = 4, ["x"] = 7, ["name"] = "default:sandstone", ["z"] = 4, ["meta"] = {["inventory"] = {}, ["fields"] = {}}}, {["y"] = 4, ["x"] = 7, ["name"] = "default:sandstone", ["z"] = 5, ["meta"] = {["inventory"] = {}, ["fields"] = {}}}, {["y"] = 4, ["x"] = 7, ["name"] = "default:sandstone", ["z"] = 6, ["meta"] = {["inventory"] = {}, ["fields"] = {}}}, {["y"] = 4, ["x"] = 7, ["name"] = "default:sandstone", ["z"] = 7, ["meta"] = {["inventory"] = {}, ["fields"] = {}}}, {["y"] = 4, ["x"] = 7, ["name"] = "default:sandstone", ["z"] = 8, ["meta"] = {["inventory"] = {}, ["fields"] = {}}}, {["y"] = 4, ["x"] = 7, ["name"] = "default:sandstone", ["z"] = 9, ["meta"] = {["inventory"] = {}, ["fields"] = {}}}, {["y"] = 4, ["x"] = 7, ["name"] = "default:sandstone", ["z"] = 10, ["meta"] = {["inventory"] = {}, ["fields"] = {}}}, {["y"] = 4, ["x"] = 7, ["name"] = "default:sandstone", ["z"] = 11, ["meta"] = {["inventory"] = {}, ["fields"] = {}}}, {["y"] = 5, ["x"] = 7, ["name"] = "default:acacia_wood", ["z"] = 1, ["meta"] = {["inventory"] = {}, ["fields"] = {}}}, {["y"] = 5, ["x"] = 7, ["name"] = "default:acacia_wood", ["z"] = 5, ["meta"] = {["inventory"] = {}, ["fields"] = {}}}, {["y"] = 5, ["x"] = 7, ["name"] = "default:acacia_wood", ["z"] = 11, ["meta"] = {["inventory"] = {}, ["fields"] = {}}}, {["y"] = 6, ["x"] = 7, ["name"] = "xpanes:pane_5", ["z"] = 1, ["meta"] = {["inventory"] = {}, ["fields"] = {}}, ["param1"] = 173}, {["y"] = 6, ["x"] = 7, ["name"] = "default:acacia_wood", ["z"] = 5, ["meta"] = {["inventory"] = {}, ["fields"] = {}}}, {["y"] = 6, ["x"] = 7, ["name"] = "default:wood", ["z"] = 11, ["meta"] = {["inventory"] = {}, ["fields"] = {}}}, {["y"] = 7, ["x"] = 7, ["name"] = "xpanes:pane_5", ["z"] = 1, ["meta"] = {["inventory"] = {}, ["fields"] = {}}, ["param1"] = 189}, {["y"] = 7, ["x"] = 7, ["name"] = "default:wood", ["z"] = 5, ["meta"] = {["inventory"] = {}, ["fields"] = {}}}, {["y"] = 7, ["x"] = 7, ["name"] = "default:wood", ["z"] = 11, ["meta"] = {["inventory"] = {}, ["fields"] = {}}}, {["y"] = 8, ["x"] = 7, ["name"] = "default:sandstonebrick", ["z"] = 1, ["meta"] = {["inventory"] = {}, ["fields"] = {}}}, {["y"] = 8, ["x"] = 7, ["name"] = "default:sandstonebrick", ["z"] = 2, ["meta"] = {["inventory"] = {}, ["fields"] = {}}}, {["y"] = 8, ["x"] = 7, ["name"] = "default:sandstonebrick", ["z"] = 3, ["meta"] = {["inventory"] = {}, ["fields"] = {}}}, {["y"] = 8, ["x"] = 7, ["name"] = "default:sandstonebrick", ["z"] = 4, ["meta"] = {["inventory"] = {}, ["fields"] = {}}}, {["y"] = 8, ["x"] = 7, ["name"] = "default:sandstonebrick", ["z"] = 5, ["meta"] = {["inventory"] = {}, ["fields"] = {}}}, {["y"] = 8, ["x"] = 7, ["name"] = "default:sandstonebrick", ["z"] = 6, ["meta"] = {["inventory"] = {}, ["fields"] = {}}}, {["y"] = 8, ["x"] = 7, ["name"] = "default:sandstonebrick", ["z"] = 7, ["meta"] = {["inventory"] = {}, ["fields"] = {}}}, {["y"] = 8, ["x"] = 7, ["name"] = "default:sandstonebrick", ["z"] = 8, ["meta"] = {["inventory"] = {}, ["fields"] = {}}}, {["y"] = 8, ["x"] = 7, ["name"] = "default:sandstonebrick", ["z"] = 9, ["meta"] = {["inventory"] = {}, ["fields"] = {}}}, {["y"] = 8, ["x"] = 7, ["name"] = "default:sandstonebrick", ["z"] = 10, ["meta"] = {["inventory"] = {}, ["fields"] = {}}}, {["y"] = 8, ["x"] = 7, ["name"] = "default:sandstonebrick", ["z"] = 11, ["meta"] = {["inventory"] = {}, ["fields"] = {}}}, {["y"] = 9, ["x"] = 7, ["name"] = "moreblocks:panel_sandstonebrick", ["z"] = 1, ["meta"] = {["inventory"] = {}, ["fields"] = {}}, ["param1"] = 127}, {["y"] = 9, ["x"] = 7, ["name"] = "default:sandstonebrick", ["z"] = 2, ["meta"] = {["inventory"] = {}, ["fields"] = {}}}, {["y"] = 9, ["x"] = 7, ["name"] = "default:sandstonebrick", ["z"] = 10, ["meta"] = {["inventory"] = {}, ["fields"] = {}}}, {["y"] = 9, ["x"] = 7, ["name"] = "moreblocks:panel_sandstonebrick", ["z"] = 11, ["meta"] = {["inventory"] = {}, ["fields"] = {}}, ["param2"] = 2, ["param1"] = 95}, {["y"] = 10, ["x"] = 7, ["name"] = "moreblocks:panel_sandstonebrick", ["z"] = 2, ["meta"] = {["inventory"] = {}, ["fields"] = {}}, ["param1"] = 95}, {["y"] = 10, ["x"] = 7, ["name"] = "default:sandstonebrick", ["z"] = 3, ["meta"] = {["inventory"] = {}, ["fields"] = {}}}, {["y"] = 10, ["x"] = 7, ["name"] = "default:sandstonebrick", ["z"] = 9, ["meta"] = {["inventory"] = {}, ["fields"] = {}}}, {["y"] = 10, ["x"] = 7, ["name"] = "moreblocks:panel_sandstonebrick", ["z"] = 10, ["meta"] = {["inventory"] = {}, ["fields"] = {}}, ["param2"] = 2, ["param1"] = 79}, {["y"] = 11, ["x"] = 7, ["name"] = "moreblocks:panel_sandstonebrick", ["z"] = 3, ["meta"] = {["inventory"] = {}, ["fields"] = {}}, ["param1"] = 63}, {["y"] = 11, ["x"] = 7, ["name"] = "default:sandstonebrick", ["z"] = 4, ["meta"] = {["inventory"] = {}, ["fields"] = {}}}, {["y"] = 11, ["x"] = 7, ["name"] = "default:sandstonebrick", ["z"] = 8, ["meta"] = {["inventory"] = {}, ["fields"] = {}}}, {["y"] = 11, ["x"] = 7, ["name"] = "moreblocks:panel_sandstonebrick", ["z"] = 9, ["meta"] = {["inventory"] = {}, ["fields"] = {}}, ["param2"] = 2, ["param1"] = 47}, {["y"] = 12, ["x"] = 7, ["name"] = "moreblocks:panel_sandstonebrick", ["z"] = 4, ["meta"] = {["inventory"] = {}, ["fields"] = {}}, ["param1"] = 31}, {["y"] = 12, ["x"] = 7, ["name"] = "default:sandstonebrick", ["z"] = 5, ["meta"] = {["inventory"] = {}, ["fields"] = {}}}, {["y"] = 12, ["x"] = 7, ["name"] = "default:sandstonebrick", ["z"] = 7, ["meta"] = {["inventory"] = {}, ["fields"] = {}}}, {["y"] = 12, ["x"] = 7, ["name"] = "moreblocks:panel_sandstonebrick", ["z"] = 8, ["meta"] = {["inventory"] = {}, ["fields"] = {}}, ["param2"] = 2, ["param1"] = 15}, {["y"] = 13, ["x"] = 7, ["name"] = "moreblocks:panel_sandstonebrick", ["z"] = 5, ["meta"] = {["inventory"] = {}, ["fields"] = {}}, ["param1"] = 15}, {["y"] = 13, ["x"] = 7, ["name"] = "default:sandstonebrick", ["z"] = 6, ["meta"] = {["inventory"] = {}, ["fields"] = {}}}, {["y"] = 13, ["x"] = 7, ["name"] = "moreblocks:panel_sandstonebrick", ["z"] = 7, ["meta"] = {["inventory"] = {}, ["fields"] = {}}, ["param2"] = 2, ["param1"] = 15}, {["y"] = 0, ["x"] = 8, ["name"] = "default:dirt_with_grass", ["z"] = 0, ["meta"] = {["inventory"] = {}, ["fields"] = {}}}, {["y"] = 0, ["x"] = 8, ["name"] = "default:dirt", ["z"] = 1, ["meta"] = {["inventory"] = {}, ["fields"] = {}}}, {["y"] = 0, ["x"] = 8, ["name"] = "default:stone", ["z"] = 2, ["meta"] = {["inventory"] = {}, ["fields"] = {}}}, {["y"] = 0, ["x"] = 8, ["name"] = "default:stone", ["z"] = 3, ["meta"] = {["inventory"] = {}, ["fields"] = {}}}, {["y"] = 0, ["x"] = 8, ["name"] = "default:stone", ["z"] = 4, ["meta"] = {["inventory"] = {}, ["fields"] = {}}}, {["y"] = 0, ["x"] = 8, ["name"] = "default:stone", ["z"] = 5, ["meta"] = {["inventory"] = {}, ["fields"] = {}}}, {["y"] = 0, ["x"] = 8, ["name"] = "default:stone", ["z"] = 6, ["meta"] = {["inventory"] = {}, ["fields"] = {}}}, {["y"] = 0, ["x"] = 8, ["name"] = "default:stone", ["z"] = 7, ["meta"] = {["inventory"] = {}, ["fields"] = {}}}, {["y"] = 0, ["x"] = 8, ["name"] = "default:stone", ["z"] = 8, ["meta"] = {["inventory"] = {}, ["fields"] = {}}}, {["y"] = 0, ["x"] = 8, ["name"] = "default:stone", ["z"] = 9, ["meta"] = {["inventory"] = {}, ["fields"] = {}}}, {["y"] = 0, ["x"] = 8, ["name"] = "default:stone", ["z"] = 10, ["meta"] = {["inventory"] = {}, ["fields"] = {}}}, {["y"] = 0, ["x"] = 8, ["name"] = "default:dirt", ["z"] = 11, ["meta"] = {["inventory"] = {}, ["fields"] = {}}}, {["y"] = 1, ["x"] = 8, ["name"] = "default:acacia_wood", ["z"] = 1, ["meta"] = {["inventory"] = {}, ["fields"] = {}}}, {["y"] = 1, ["x"] = 8, ["name"] = "default:furnace", ["z"] = 2, ["meta"] = {["inventory"] = {["dst"] = {"", "", "", ""}, ["src"] = {""}, ["fuel"] = {"homedecor:oil_extract 46"}}, ["fields"] = {["src_time"] = "0", ["fuel_totaltime"] = "0", ["infotext"] = "Furnace inactive (Item: Empty; Fuel: 0%)", ["formspec"] = "size[8,8.5]bgcolor[#080808BB;true]background[5,5;1,1;gui_formbg.png;true]listcolors[#00000069;#5A5A5A;#141318;#30434C;#FFF]list[current_name;src;2.75,0.5;1,1;]list[current_name;fuel;2.75,2.5;1,1;]image[2.75,1.5;1,1;default_furnace_fire_bg.png]image[3.75,1.5;1,1;gui_furnace_arrow_bg.png^[transformR270]list[current_name;dst;4.75,0.96;2,2;]list[current_player;main;0,4.25;8,1;]list[current_player;main;0,5.5;8,3;8]listring[current_name;dst]listring[current_player;main]listring[current_name;src]listring[current_player;main]image[0,4.25;1,1;gui_hb_bg.png]image[1,4.25;1,1;gui_hb_bg.png]image[2,4.25;1,1;gui_hb_bg.png]image[3,4.25;1,1;gui_hb_bg.png]image[4,4.25;1,1;gui_hb_bg.png]image[5,4.25;1,1;gui_hb_bg.png]image[6,4.25;1,1;gui_hb_bg.png]image[7,4.25;1,1;gui_hb_bg.png]", ["fuel_time"] = "0"}}, ["param2"] = 1}, {["y"] = 1, ["x"] = 8, ["name"] = "default:chest", ["z"] = 3, ["meta"] = {["inventory"] = {["main"] = {"homedecor:wood_table_small_round", "homedecor:wood_table_large 2", "homedecor:wood_table_small_square 12", "", "", "", "", "screwdriver:screwdriver", "xpanes:pane", "default:glass 4", "", "", "", "", "", "", "", "", "", "", "", "", "", "", "homedecor:plastic_sheeting 46", "homedecor:paraffin 32", "default:paper 18", "homedecor:door_wood_plain_left", "cottages:handmill", "homedecor:pole_wrought_iron 3", "fire:flint_and_steel", "building_blocks:sticks"}}, ["fields"] = {["formspec"] = "size[8,9]bgcolor[#080808BB;true]background[5,5;1,1;gui_formbg.png;true]listcolors[#00000069;#5A5A5A;#141318;#30434C;#FFF]list[current_name;main;0,0.3;8,4;]list[current_player;main;0,4.85;8,1;]list[current_player;main;0,6.08;8,3;8]listring[current_name;main]listring[current_player;main]image[0,4.85;1,1;gui_hb_bg.png]image[1,4.85;1,1;gui_hb_bg.png]image[2,4.85;1,1;gui_hb_bg.png]image[3,4.85;1,1;gui_hb_bg.png]image[4,4.85;1,1;gui_hb_bg.png]image[5,4.85;1,1;gui_hb_bg.png]image[6,4.85;1,1;gui_hb_bg.png]image[7,4.85;1,1;gui_hb_bg.png]", ["infotext"] = "Chest"}}, ["param2"] = 1}, {["y"] = 1, ["x"] = 8, ["name"] = "default:chest", ["z"] = 4, ["meta"] = {["inventory"] = {["main"] = {"default:sapling 20", "default:acacia_sapling 13", "default:aspen_sapling 2", "", "", "farming:flour", "", "farming:seed_wheat 4", "default:acacia_leaves 5", "default:aspen_leaves", "default:leaves 14", "default:dry_grass_1 79", "", "", "", "", "", "", "", "", "default:papyrus 30", "", "default:papyrus 38", "", "default:apple 85", "flowers:mushroom_brown 8", "flowers:mushroom_red 10", "flowers:waterlily 14", "default:dry_shrub 4", "default:grass_1 70", "farming_plus:carrot_item 2", ""}}, ["fields"] = {["formspec"] = "size[8,9]bgcolor[#080808BB;true]background[5,5;1,1;gui_formbg.png;true]listcolors[#00000069;#5A5A5A;#141318;#30434C;#FFF]list[current_name;main;0,0.3;8,4;]list[current_player;main;0,4.85;8,1;]list[current_player;main;0,6.08;8,3;8]listring[current_name;main]listring[current_player;main]image[0,4.85;1,1;gui_hb_bg.png]image[1,4.85;1,1;gui_hb_bg.png]image[2,4.85;1,1;gui_hb_bg.png]image[3,4.85;1,1;gui_hb_bg.png]image[4,4.85;1,1;gui_hb_bg.png]image[5,4.85;1,1;gui_hb_bg.png]image[6,4.85;1,1;gui_hb_bg.png]image[7,4.85;1,1;gui_hb_bg.png]", ["infotext"] = "Chest"}}, ["param2"] = 1}, {["y"] = 1, ["x"] = 8, ["name"] = "default:chest", ["z"] = 5, ["meta"] = {["inventory"] = {["main"] = {"default:gravel 42", "", "", "", "default:obsidian 4", "", "", "default:dirt 99", "default:mossycobble 29", "default:cobble 74", "moreblocks:panel_cobble 8", "walls:cobble 2", "", "", "", "default:dirt 99", "default:stone 95", "", "", "", "", "", "", "", "", "default:sandstone 54", "default:sand 81", "moreblocks:panel_sandstone 10", "default:sandstonebrick 37", "moreblocks:panel_sandstonebrick 19", "", "moreblocks:cobble_compressed"}}, ["fields"] = {["formspec"] = "size[8,9]bgcolor[#080808BB;true]background[5,5;1,1;gui_formbg.png;true]listcolors[#00000069;#5A5A5A;#141318;#30434C;#FFF]list[current_name;main;0,0.3;8,4;]list[current_player;main;0,4.85;8,1;]list[current_player;main;0,6.08;8,3;8]listring[current_name;main]listring[current_player;main]image[0,4.85;1,1;gui_hb_bg.png]image[1,4.85;1,1;gui_hb_bg.png]image[2,4.85;1,1;gui_hb_bg.png]image[3,4.85;1,1;gui_hb_bg.png]image[4,4.85;1,1;gui_hb_bg.png]image[5,4.85;1,1;gui_hb_bg.png]image[6,4.85;1,1;gui_hb_bg.png]image[7,4.85;1,1;gui_hb_bg.png]", ["infotext"] = "Chest"}}, ["param2"] = 1}, {["y"] = 1, ["x"] = 8, ["name"] = "default:chest", ["z"] = 6, ["meta"] = {["inventory"] = {["main"] = {"default:copper_ingot 7", "default:copper_lump 17", "default:gold_lump 6", "default:steel_ingot 11", "", "", "", "", "", "default:flint", "default:iron_lump 28", "", "default:coal_lump 35", "", "", "", "", "", "", "", "", "", "", "", "", "", "", "", "", "", "", ""}}, ["fields"] = {["formspec"] = "size[8,9]bgcolor[#080808BB;true]background[5,5;1,1;gui_formbg.png;true]listcolors[#00000069;#5A5A5A;#141318;#30434C;#FFF]list[current_name;main;0,0.3;8,4;]list[current_player;main;0,4.85;8,1;]list[current_player;main;0,6.08;8,3;8]listring[current_name;main]listring[current_player;main]image[0,4.85;1,1;gui_hb_bg.png]image[1,4.85;1,1;gui_hb_bg.png]image[2,4.85;1,1;gui_hb_bg.png]image[3,4.85;1,1;gui_hb_bg.png]image[4,4.85;1,1;gui_hb_bg.png]image[5,4.85;1,1;gui_hb_bg.png]image[6,4.85;1,1;gui_hb_bg.png]image[7,4.85;1,1;gui_hb_bg.png]", ["infotext"] = "Chest"}}, ["param2"] = 1}, {["y"] = 1, ["x"] = 8, ["name"] = "default:chest", ["z"] = 7, ["meta"] = {["inventory"] = {["main"] = {"", "", "", "", "", "", "", "", "", "", "", "", "", "", "", "", "", "", "", "", "", "", "", "", "default:acacia_tree", "default:acacia_wood 16", "moreblocks:panel_acacia_wood 4", "default:aspen_wood 21", "default:fence_aspen_wood 8", "stairs:slab_wood", "moreblocks:panel_wood 4", ""}}, ["fields"] = {["formspec"] = "size[8,9]bgcolor[#080808BB;true]background[5,5;1,1;gui_formbg.png;true]listcolors[#00000069;#5A5A5A;#141318;#30434C;#FFF]list[current_name;main;0,0.3;8,4;]list[current_player;main;0,4.85;8,1;]list[current_player;main;0,6.08;8,3;8]listring[current_name;main]listring[current_player;main]image[0,4.85;1,1;gui_hb_bg.png]image[1,4.85;1,1;gui_hb_bg.png]image[2,4.85;1,1;gui_hb_bg.png]image[3,4.85;1,1;gui_hb_bg.png]image[4,4.85;1,1;gui_hb_bg.png]image[5,4.85;1,1;gui_hb_bg.png]image[6,4.85;1,1;gui_hb_bg.png]image[7,4.85;1,1;gui_hb_bg.png]", ["infotext"] = "Chest"}}, ["param2"] = 1}, {["y"] = 1, ["x"] = 8, ["name"] = "default:acacia_wood", ["z"] = 11, ["meta"] = {["inventory"] = {}, ["fields"] = {}}}, {["y"] = 2, ["x"] = 8, ["name"] = "default:acacia_wood", ["z"] = 1, ["meta"] = {["inventory"] = {}, ["fields"] = {}}}, {["y"] = 2, ["x"] = 8, ["name"] = "default:acacia_wood", ["z"] = 11, ["meta"] = {["inventory"] = {}, ["fields"] = {}}}, {["y"] = 3, ["x"] = 8, ["name"] = "default:wood", ["z"] = 1, ["meta"] = {["inventory"] = {}, ["fields"] = {}}}, {["y"] = 3, ["x"] = 8, ["name"] = "homedecor:glowlight_small_cube_white", ["z"] = 2, ["meta"] = {["inventory"] = {}, ["fields"] = {}}, ["param2"] = 18}, {["y"] = 3, ["x"] = 8, ["name"] = "homedecor:glowlight_small_cube_white", ["z"] = 6, ["meta"] = {["inventory"] = {}, ["fields"] = {}}, ["param2"] = 18}, {["y"] = 3, ["x"] = 8, ["name"] = "homedecor:glowlight_small_cube_white", ["z"] = 10, ["meta"] = {["inventory"] = {}, ["fields"] = {}}, ["param2"] = 18}, {["y"] = 3, ["x"] = 8, ["name"] = "default:wood", ["z"] = 11, ["meta"] = {["inventory"] = {}, ["fields"] = {}}}, {["y"] = 4, ["x"] = 8, ["name"] = "default:sandstone", ["z"] = 1, ["meta"] = {["inventory"] = {}, ["fields"] = {}}}, {["y"] = 4, ["x"] = 8, ["name"] = "default:sandstone", ["z"] = 2, ["meta"] = {["inventory"] = {}, ["fields"] = {}}}, {["y"] = 4, ["x"] = 8, ["name"] = "default:sandstone", ["z"] = 3, ["meta"] = {["inventory"] = {}, ["fields"] = {}}}, {["y"] = 4, ["x"] = 8, ["name"] = "default:sandstone", ["z"] = 4, ["meta"] = {["inventory"] = {}, ["fields"] = {}}}, {["y"] = 4, ["x"] = 8, ["name"] = "default:sandstone", ["z"] = 5, ["meta"] = {["inventory"] = {}, ["fields"] = {}}}, {["y"] = 4, ["x"] = 8, ["name"] = "default:sandstone", ["z"] = 6, ["meta"] = {["inventory"] = {}, ["fields"] = {}}}, {["y"] = 4, ["x"] = 8, ["name"] = "default:sandstone", ["z"] = 7, ["meta"] = {["inventory"] = {}, ["fields"] = {}}}, {["y"] = 4, ["x"] = 8, ["name"] = "default:sandstone", ["z"] = 8, ["meta"] = {["inventory"] = {}, ["fields"] = {}}}, {["y"] = 4, ["x"] = 8, ["name"] = "default:sandstone", ["z"] = 9, ["meta"] = {["inventory"] = {}, ["fields"] = {}}}, {["y"] = 4, ["x"] = 8, ["name"] = "default:sandstone", ["z"] = 10, ["meta"] = {["inventory"] = {}, ["fields"] = {}}}, {["y"] = 4, ["x"] = 8, ["name"] = "default:sandstone", ["z"] = 11, ["meta"] = {["inventory"] = {}, ["fields"] = {}}}, {["y"] = 5, ["x"] = 8, ["name"] = "default:acacia_wood", ["z"] = 1, ["meta"] = {["inventory"] = {}, ["fields"] = {}}}, {["y"] = 5, ["x"] = 8, ["name"] = "default:acacia_wood", ["z"] = 5, ["meta"] = {["inventory"] = {}, ["fields"] = {}}}, {["y"] = 5, ["x"] = 8, ["name"] = "default:acacia_wood", ["z"] = 11, ["meta"] = {["inventory"] = {}, ["fields"] = {}}}, {["y"] = 6, ["x"] = 8, ["name"] = "default:acacia_wood", ["z"] = 1, ["meta"] = {["inventory"] = {}, ["fields"] = {}}}, {["y"] = 6, ["x"] = 8, ["name"] = "default:acacia_wood", ["z"] = 5, ["meta"] = {["inventory"] = {}, ["fields"] = {}}}, {["y"] = 6, ["x"] = 8, ["name"] = "default:acacia_wood", ["z"] = 11, ["meta"] = {["inventory"] = {}, ["fields"] = {}}}, {["y"] = 7, ["x"] = 8, ["name"] = "default:wood", ["z"] = 1, ["meta"] = {["inventory"] = {}, ["fields"] = {}}}, {["y"] = 7, ["x"] = 8, ["name"] = "homedecor:glowlight_small_cube_white", ["z"] = 2, ["meta"] = {["inventory"] = {}, ["fields"] = {}}, ["param2"] = 22}, {["y"] = 7, ["x"] = 8, ["name"] = "default:wood", ["z"] = 5, ["meta"] = {["inventory"] = {}, ["fields"] = {}}}, {["y"] = 7, ["x"] = 8, ["name"] = "default:wood", ["z"] = 11, ["meta"] = {["inventory"] = {}, ["fields"] = {}}}, {["y"] = 8, ["x"] = 8, ["name"] = "default:sandstonebrick", ["z"] = 1, ["meta"] = {["inventory"] = {}, ["fields"] = {}}}, {["y"] = 8, ["x"] = 8, ["name"] = "default:sandstonebrick", ["z"] = 2, ["meta"] = {["inventory"] = {}, ["fields"] = {}}}, {["y"] = 8, ["x"] = 8, ["name"] = "default:sandstonebrick", ["z"] = 3, ["meta"] = {["inventory"] = {}, ["fields"] = {}}}, {["y"] = 8, ["x"] = 8, ["name"] = "default:sandstonebrick", ["z"] = 4, ["meta"] = {["inventory"] = {}, ["fields"] = {}}}, {["y"] = 8, ["x"] = 8, ["name"] = "default:sandstonebrick", ["z"] = 5, ["meta"] = {["inventory"] = {}, ["fields"] = {}}}, {["y"] = 8, ["x"] = 8, ["name"] = "default:sandstonebrick", ["z"] = 6, ["meta"] = {["inventory"] = {}, ["fields"] = {}}}, {["y"] = 8, ["x"] = 8, ["name"] = "default:sandstonebrick", ["z"] = 7, ["meta"] = {["inventory"] = {}, ["fields"] = {}}}, {["y"] = 8, ["x"] = 8, ["name"] = "default:sandstonebrick", ["z"] = 8, ["meta"] = {["inventory"] = {}, ["fields"] = {}}}, {["y"] = 8, ["x"] = 8, ["name"] = "default:sandstonebrick", ["z"] = 9, ["meta"] = {["inventory"] = {}, ["fields"] = {}}}, {["y"] = 8, ["x"] = 8, ["name"] = "default:sandstonebrick", ["z"] = 10, ["meta"] = {["inventory"] = {}, ["fields"] = {}}}, {["y"] = 8, ["x"] = 8, ["name"] = "default:sandstonebrick", ["z"] = 11, ["meta"] = {["inventory"] = {}, ["fields"] = {}}}, {["y"] = 9, ["x"] = 8, ["name"] = "moreblocks:panel_sandstonebrick", ["z"] = 1, ["meta"] = {["inventory"] = {}, ["fields"] = {}}, ["param1"] = 111}, {["y"] = 9, ["x"] = 8, ["name"] = "default:sandstonebrick", ["z"] = 2, ["meta"] = {["inventory"] = {}, ["fields"] = {}}}, {["y"] = 9, ["x"] = 8, ["name"] = "torches:floor", ["z"] = 3, ["meta"] = {["inventory"] = {}, ["fields"] = {}}, ["param2"] = 1}, {["y"] = 9, ["x"] = 8, ["name"] = "torches:floor", ["z"] = 9, ["meta"] = {["inventory"] = {}, ["fields"] = {}}, ["param2"] = 1}, {["y"] = 9, ["x"] = 8, ["name"] = "default:sandstonebrick", ["z"] = 10, ["meta"] = {["inventory"] = {}, ["fields"] = {}}}, {["y"] = 9, ["x"] = 8, ["name"] = "moreblocks:panel_sandstonebrick", ["z"] = 11, ["meta"] = {["inventory"] = {}, ["fields"] = {}}, ["param2"] = 2, ["param1"] = 95}, {["y"] = 10, ["x"] = 8, ["name"] = "moreblocks:panel_sandstonebrick", ["z"] = 2, ["meta"] = {["inventory"] = {}, ["fields"] = {}}, ["param1"] = 79}, {["y"] = 10, ["x"] = 8, ["name"] = "default:sandstonebrick", ["z"] = 3, ["meta"] = {["inventory"] = {}, ["fields"] = {}}}, {["y"] = 10, ["x"] = 8, ["name"] = "default:sandstonebrick", ["z"] = 9, ["meta"] = {["inventory"] = {}, ["fields"] = {}}}, {["y"] = 10, ["x"] = 8, ["name"] = "moreblocks:panel_sandstonebrick", ["z"] = 10, ["meta"] = {["inventory"] = {}, ["fields"] = {}}, ["param2"] = 2, ["param1"] = 95}, {["y"] = 11, ["x"] = 8, ["name"] = "moreblocks:panel_sandstonebrick", ["z"] = 3, ["meta"] = {["inventory"] = {}, ["fields"] = {}}, ["param1"] = 47}, {["y"] = 11, ["x"] = 8, ["name"] = "default:sandstonebrick", ["z"] = 4, ["meta"] = {["inventory"] = {}, ["fields"] = {}}}, {["y"] = 11, ["x"] = 8, ["name"] = "default:sandstonebrick", ["z"] = 8, ["meta"] = {["inventory"] = {}, ["fields"] = {}}}, {["y"] = 11, ["x"] = 8, ["name"] = "moreblocks:panel_sandstonebrick", ["z"] = 9, ["meta"] = {["inventory"] = {}, ["fields"] = {}}, ["param2"] = 2, ["param1"] = 63}, {["y"] = 12, ["x"] = 8, ["name"] = "moreblocks:panel_sandstonebrick", ["z"] = 4, ["meta"] = {["inventory"] = {}, ["fields"] = {}}, ["param1"] = 15}, {["y"] = 12, ["x"] = 8, ["name"] = "default:sandstonebrick", ["z"] = 5, ["meta"] = {["inventory"] = {}, ["fields"] = {}}}, {["y"] = 12, ["x"] = 8, ["name"] = "default:sandstonebrick", ["z"] = 7, ["meta"] = {["inventory"] = {}, ["fields"] = {}}}, {["y"] = 12, ["x"] = 8, ["name"] = "moreblocks:panel_sandstonebrick", ["z"] = 8, ["meta"] = {["inventory"] = {}, ["fields"] = {}}, ["param2"] = 2, ["param1"] = 31}, {["y"] = 13, ["x"] = 8, ["name"] = "moreblocks:panel_sandstonebrick", ["z"] = 5, ["meta"] = {["inventory"] = {}, ["fields"] = {}}, ["param1"] = 15}, {["y"] = 13, ["x"] = 8, ["name"] = "default:sandstonebrick", ["z"] = 6, ["meta"] = {["inventory"] = {}, ["fields"] = {}}}, {["y"] = 13, ["x"] = 8, ["name"] = "moreblocks:panel_sandstonebrick", ["z"] = 7, ["meta"] = {["inventory"] = {}, ["fields"] = {}}, ["param2"] = 2, ["param1"] = 15}, {["y"] = 0, ["x"] = 9, ["name"] = "default:dirt_with_grass", ["z"] = 0, ["meta"] = {["inventory"] = {}, ["fields"] = {}}},